Workbook

Sheet CRUSCOTTO
B2: Genere | C2: Sottogenere | D2: # TOT schede | F2: # Ordinarie | G2: # Varianti | H2: Avanzamento | I2: # Mancanti | J2: Valore G25 | L2: Ordinarie | P2: Varianti | T2: Genere | U2: Sottogenere | V2: # TOT schede | X2: # In collezione | Y2: Varianti | Z2: Avanzamento | AA2: # Mancanti | AB2: Valore G26
L3: Nuove | M3: Usate | N3: 2a Scelta | O3: Mancanti | P3: Nuove | Q3: Usate | R3: 2a Scelta | S3: Mancanti
B4: Precursorie | C4: 1. Sida | D4: =SUM(E4:E7) -> 287 | E4: =IF(COUNTIF('1. Precursorie'!B:B,CRUSCOTTO!C4)=(CRUSCOTTO!F4+CRUSCOTTO!G4),CRUSCOTTO!F4+CRUSCOTTO!G4,"Errore") -> 99 | F4: =COUNTIFS('1. Precursorie'!B:B,CRUSCOTTO!C4,'1. Precursorie'!J:J,"-") -> 60 | G4: =COUNTIFS('1. Precursorie'!B:B,CRUSCOTTO!C4,'1. Precursorie'!J:J,"Variante") -> 39 | H4: =(E4-I4)/E4 -> 0.74747475 | I4: =IF(G4=0,O4,O4+S4) -> 25 | J4: =SUMIF('1. Precursorie'!B:B,CRUSCOTTO!C4,'1. Precursorie'!S:S) -> 3630 | L4: =COUNTIFS('1. Precursorie'!B:B,CRUSCOTTO!C4,'1. Precursorie'!J:J,"-",'1. Precursorie'!P:P,"Nuova") -> 26 | M4: =COUNTIFS('1. Precursorie'!B:B,CRUSCOTTO!C4,'1. Precursorie'!J:J,"-",'1. Precursorie'!P:P,"Usata") -> 24 | N4: =COUNTIFS('1. Precursorie'!B:B,CRUSCOTTO!C4,'1. Precursorie'!J:J,"-",'1. Precursorie'!P:P,"2a scelta") -> 1 | O4: =COUNTIFS('1. Precursorie'!B:B,CRUSCOTTO!C4,'1. Precursorie'!J:J,"-",'1. Precursorie'!P:P,"Manca") -> 9 | P4: =IF(G4=0,"-",COUNTIFS('1. Precursorie'!B:B,CRUSCOTTO!C4,'1. Precursorie'!J:J,"Variante",'1. Precursorie'!P:P,"Nuova")) -> 8 | Q4: =IF(G4=0,"-",COUNTIFS('1. Precursorie'!B:B,CRUSCOTTO!C4,'1. Precursorie'!J:J,"Variante",'1. Precursorie'!P:P,"Usata")) -> 13 | R4: =IF(G4=0,"-",COUNTIFS('1. Precursorie'!B:B,CRUSCOTTO!C4,'1. Precursorie'!J:J,"Variante",'1. Precursorie'!P:P,"2a scelta")) -> 2 | S4: =IF(G4=0,"-",COUNTIFS('1. Precursorie'!B:B,CRUSCOTTO!C4,'1. Precursorie'!J:J,"Variante",'1. Precursorie'!P:P,"Manca")) -> 16 | T4: Internazionali | U4: 1. Ordinarie | V4: =SUM(W4:W7) -> 767 | W4: =COUNTIF('13. Internazionali'!B:B,"13. Internazionali")-COUNTIF('13. Internazionali'!P:P,"n/a") -> 332 | X4: =COUNTIF('13. Internazionali'!P:P,"Nuova")+COUNTIF('13. Internazionali'!P:P,"Usata")+COUNTIF('13. Internazionali'!P:P,"2a Scelta") -> 190 | Y4: - | Z4: =(X4)/W4 -> 0.57228916 | AA4: =COUNTIF('13. Internazionali'!P:P,"Manca") -> 138 | AB4: =SUMIF('13. Internazionali'!P:P,"Usata",'13. Internazionali'!M:M)+1.5*SUMIF('13. Internazionali'!P:P,"Nuova",'13. Internazionali'!M:M) -> 1216.5
C5: 2. Urmet | E5: =IF(COUNTIF('1. Precursorie'!B:B,CRUSCOTTO!C5)=(CRUSCOTTO!F5+CRUSCOTTO!G5),CRUSCOTTO!F5+CRUSCOTTO!G5,"Errore") -> 23 | F5: =COUNTIFS('1. Precursorie'!B:B,CRUSCOTTO!C5,'1. Precursorie'!J:J,"-") -> 13 | G5: =COUNTIFS('1. Precursorie'!B:B,CRUSCOTTO!C5,'1. Precursorie'!J:J,"Variante") -> 10 | H5: =(E5-I5)/E5 -> 0.95652174 | I5: =IF(G5=0,O5,O5+S5) -> 1 | J5: =SUMIF('1. Precursorie'!B:B,CRUSCOTTO!C5,'1. Precursorie'!S:S) -> 2342 | L5: =COUNTIFS('1. Precursorie'!B:B,CRUSCOTTO!C5,'1. Precursorie'!J:J,"-",'1. Precursorie'!P:P,"Nuova") -> 10 | M5: =COUNTIFS('1. Precursorie'!B:B,CRUSCOTTO!C5,'1. Precursorie'!J:J,"-",'1. Precursorie'!P:P,"Usata") -> 3 | N5: =COUNTIFS('1. Precursorie'!B:B,CRUSCOTTO!C5,'1. Precursorie'!J:J,"-",'1. Precursorie'!P:P,"2a scelta") -> 0 | O5: =COUNTIFS('1. Precursorie'!B:B,CRUSCOTTO!C5,'1. Precursorie'!J:J,"-",'1. Precursorie'!P:P,"Manca") -> 0 | P5: =IF(G5=0,"-",COUNTIFS('1. Precursorie'!B:B,CRUSCOTTO!C5,'1. Precursorie'!J:J,"Variante",'1. Precursorie'!P:P,"Nuova")) -> 4 | Q5: =IF(G5=0,"-",COUNTIFS('1. Precursorie'!B:B,CRUSCOTTO!C5,'1. Precursorie'!J:J,"Variante",'1. Precursorie'!P:P,"Usata")) -> 5 | R5: =IF(G5=0,"-",COUNTIFS('1. Precursorie'!B:B,CRUSCOTTO!C5,'1. Precursorie'!J:J,"Variante",'1. Precursorie'!P:P,"2a scelta")) -> 0 | S5: =IF(G5=0,"-",COUNTIFS('1. Precursorie'!B:B,CRUSCOTTO!C5,'1. Precursorie'!J:J,"Variante",'1. Precursorie'!P:P,"Manca")) -> 1 | U5: 2. Test | W5: =COUNTIF('13. Internazionali'!B:B,"13. Internazionali")-COUNTIF('13. Internazionali'!R:R,"n/a") -> 111 | X5: =COUNTIF('13. Internazionali'!R:R,"Nuova")+COUNTIF('13. Internazionali'!R:R,"Usata")+COUNTIF('13. Internazionali'!R:R,"2a Scelta") -> 34 | Y5: - | Z5: =(X5)/W5 -> 0.30630631 | AA5: =COUNTIF('13. Internazionali'!R:R,"Manca") -> 77 | AB5: =SUMIF('13. Internazionali'!R:R,"Usata",'13. Internazionali'!N:N)+1.5*SUMIF('13. Internazionali'!R:R,"Nuova",'13. Internazionali'!N:N) -> 208
C6: 3. Studi e prove | E6: =IF(COUNTIF('1. Precursorie'!B:B,CRUSCOTTO!C6)=(CRUSCOTTO!F6+CRUSCOTTO!G6),CRUSCOTTO!F6+CRUSCOTTO!G6,"Errore") -> 11 | F6: =COUNTIFS('1. Precursorie'!B:B,CRUSCOTTO!C6,'1. Precursorie'!J:J,"-") -> 11 | G6: =COUNTIFS('1. Precursorie'!B:B,CRUSCOTTO!C6,'1. Precursorie'!J:J,"Variante") -> 0 | H6: =(E6-I6)/E6 -> 0.72727273 | I6: =IF(G6=0,O6,O6+S6) -> 3 | J6: =SUMIF('1. Precursorie'!B:B,CRUSCOTTO!C6,'1. Precursorie'!S:S) -> 400 | L6: =COUNTIFS('1. Precursorie'!B:B,CRUSCOTTO!C6,'1. Precursorie'!J:J,"-",'1. Precursorie'!P:P,"Nuova") -> 6 | M6: =COUNTIFS('1. Precursorie'!B:B,CRUSCOTTO!C6,'1. Precursorie'!J:J,"-",'1. Precursorie'!P:P,"Usata") -> 2 | N6: =COUNTIFS('1. Precursorie'!B:B,CRUSCOTTO!C6,'1. Precursorie'!J:J,"-",'1. Precursorie'!P:P,"2a scelta") -> 0 | O6: =COUNTIFS('1. Precursorie'!B:B,CRUSCOTTO!C6,'1. Precursorie'!J:J,"-",'1. Precursorie'!P:P,"Manca") -> 3 | P6: =IF(G6=0,"-",COUNTIFS('1. Precursorie'!B:B,CRUSCOTTO!C6,'1. Precursorie'!J:J,"Variante",'1. Precursorie'!P:P,"Nuova")) -> - | Q6: =IF(G6=0,"-",COUNTIFS('1. Precursorie'!B:B,CRUSCOTTO!C6,'1. Precursorie'!J:J,"Variante",'1. Precursorie'!P:P,"Usata")) -> - | R6: =IF(G6=0,"-",COUNTIFS('1. Precursorie'!B:B,CRUSCOTTO!C6,'1. Precursorie'!J:J,"Variante",'1. Precursorie'!P:P,"2a scelta")) -> - | S6: =IF(G6=0,"-",COUNTIFS('1. Precursorie'!B:B,CRUSCOTTO!C6,'1. Precursorie'!J:J,"Variante",'1. Precursorie'!P:P,"Manca")) -> - | U6: 3. Arch | W6: - | X6: =COUNTIF('13. Internazionali'!S:S,"Nuova")+COUNTIF('13. Internazionali'!S:S,"Usata")+COUNTIF('13. Internazionali'!S:S,"2a Scelta") -> 6 | Y6: - | Z6: - | AA6: - | AB6: 0
C7: 4. Turistiche | E7: =IF(COUNTIF('1. Precursorie'!B:B,CRUSCOTTO!C7)=(CRUSCOTTO!F7+CRUSCOTTO!G7),CRUSCOTTO!F7+CRUSCOTTO!G7,"Errore") -> 154 | F7: =COUNTIFS('1. Precursorie'!B:B,CRUSCOTTO!C7,'1. Precursorie'!J:J,"-") -> 125 | G7: =COUNTIFS('1. Precursorie'!B:B,CRUSCOTTO!C7,'1. Precursorie'!J:J,"Variante") -> 29 | H7: =(E7-I7)/E7 -> 0.97402597 | I7: =IF(G7=0,O7,O7+S7) -> 4 | J7: =SUMIF('1. Precursorie'!B:B,CRUSCOTTO!C7,'1. Precursorie'!S:S) -> 4764.5 | L7: =COUNTIFS('1. Precursorie'!B:B,CRUSCOTTO!C7,'1. Precursorie'!J:J,"-",'1. Precursorie'!P:P,"Nuova") -> 78 | M7: =COUNTIFS('1. Precursorie'!B:B,CRUSCOTTO!C7,'1. Precursorie'!J:J,"-",'1. Precursorie'!P:P,"Usata") -> 45 | N7: =COUNTIFS('1. Precursorie'!B:B,CRUSCOTTO!C7,'1. Precursorie'!J:J,"-",'1. Precursorie'!P:P,"2a scelta") -> 2 | O7: =COUNTIFS('1. Precursorie'!B:B,CRUSCOTTO!C7,'1. Precursorie'!J:J,"-",'1. Precursorie'!P:P,"Manca") -> 0 | P7: =IF(G7=0,"-",COUNTIFS('1. Precursorie'!B:B,CRUSCOTTO!C7,'1. Precursorie'!J:J,"Variante",'1. Precursorie'!P:P,"Nuova")) -> 15 | Q7: =IF(G7=0,"-",COUNTIFS('1. Precursorie'!B:B,CRUSCOTTO!C7,'1. Precursorie'!J:J,"Variante",'1. Precursorie'!P:P,"Usata")) -> 10 | R7: =IF(G7=0,"-",COUNTIFS('1. Precursorie'!B:B,CRUSCOTTO!C7,'1. Precursorie'!J:J,"Variante",'1. Precursorie'!P:P,"2a scelta")) -> 0 | S7: =IF(G7=0,"-",COUNTIFS('1. Precursorie'!B:B,CRUSCOTTO!C7,'1. Precursorie'!J:J,"Variante",'1. Precursorie'!P:P,"Manca")) -> 4 | U7: 4. Base | W7: =COUNTIF('13. Internazionali'!B:B,"13. Internazionali")-COUNTIF('13. Internazionali'!Q:Q,"n/a") -> 324 | X7: =COUNTIF('13. Internazionali'!Q:Q,"Nuova")+COUNTIF('13. Internazionali'!Q:Q,"Usata")+COUNTIF('13. Internazionali'!Q:Q,"2a Scelta") -> 27 | Y7: - | Z7: - | AA7: - | AB7: 0
B8: Private | C8: 1. Precursorie omaggio | D8: =SUM(E8:E10) -> 479 | E8: =IF(COUNTIF('2. Private'!B:B,CRUSCOTTO!C8)=(CRUSCOTTO!F8+CRUSCOTTO!G8),CRUSCOTTO!F8+CRUSCOTTO!G8,"Errore") -> 91 | F8: =COUNTIFS('2. Private'!B:B,CRUSCOTTO!C8,'2. Private'!K:K,"-") -> 91 | G8: =COUNTIFS('2. Private'!B:B,CRUSCOTTO!C8,'2. Private'!K:K,"Variante") -> 0 | H8: =(E8-I8)/E8 -> 0.76923077 | I8: =IF(G8=0,O8,O8+S8) -> 21 | J8: =SUMIF('2. Private'!B:B,CRUSCOTTO!C8,'2. Private'!T:T) -> 4625 | L8: =COUNTIFS('2. Private'!B:B,CRUSCOTTO!C8,'2. Private'!K:K,"-",'2. Private'!P:P,"Nuova") -> 58 | M8: =COUNTIFS('2. Private'!B:B,CRUSCOTTO!C8,'2. Private'!K:K,"-",'2. Private'!P:P,"Usata") -> 11 | N8: =COUNTIFS('2. Private'!B:B,CRUSCOTTO!C8,'2. Private'!K:K,"-",'2. Private'!P:P,"2a scelta") -> 1 | O8: =COUNTIFS('2. Private'!B:B,CRUSCOTTO!C8,'2. Private'!K:K,"-",'2. Private'!P:P,"Manca") -> 21 | P8: =IF(G8=0,"-",COUNTIFS('2. Private'!B:B,CRUSCOTTO!C8,'2. Private'!K:K,"Variante",'2. Private'!P:P,"Nuova")) -> - | Q8: =IF(G8=0,"-",COUNTIFS('2. Private'!B:B,CRUSCOTTO!C8,'2. Private'!K:K,"Variante",'2. Private'!P:P,"Usata")) -> - | R8: =IF(G8=0,"-",COUNTIFS('2. Private'!B:B,CRUSCOTTO!C8,'2. Private'!K:K,"Variante",'2. Private'!P:P,"2a scelta")) -> - | S8: =IF(G8=0,"-",COUNTIFS('2. Private'!B:B,CRUSCOTTO!C8,'2. Private'!K:K,"Variante",'2. Private'!P:P,"Manca")) -> - | T8: San Marino e Vaticano | U8: 1. San Marino | V8: =W8+W9 -> 533 | W8: =COUNTIF('14. San Marino'!A:A,"14. San Marino") -> 199 | X8: =COUNTIF('14. San Marino'!Q:Q,"Nuova")+COUNTIF('14. San Marino'!Q:Q,"Usata")+COUNTIF('14. San Marino'!Q:Q,"2a Scelta") -> 190 | Y8: =COUNTIF('14. San Marino'!I:I,"Variante") -> 4 | Z8: =X8/W8 -> 0.95477387 | AA8: =COUNTIF('14. San Marino'!Q:Q,"Manca") -> 9 | AB8: =SUM('14. San Marino'!T:T) -> 428
C9: 2. Omaggio private | E9: =IF(COUNTIF('2. Private'!B:B,CRUSCOTTO!C9)=(CRUSCOTTO!F9+CRUSCOTTO!G9),CRUSCOTTO!F9+CRUSCOTTO!G9,"Errore") -> 179 | F9: =COUNTIFS('2. Private'!B:B,CRUSCOTTO!C9,'2. Private'!K:K,"-") -> 153 | G9: =COUNTIFS('2. Private'!B:B,CRUSCOTTO!C9,'2. Private'!K:K,"Variante") -> 26 | H9: =(E9-I9)/E9 -> 0.90502793 | I9: =IF(G9=0,O9,O9+S9) -> 17 | J9: =SUMIF('2. Private'!B:B,CRUSCOTTO!C9,'2. Private'!T:T) -> 5632 | L9: =COUNTIFS('2. Private'!B:B,CRUSCOTTO!C9,'2. Private'!K:K,"-",'2. Private'!P:P,"Nuova") -> 141 | M9: =COUNTIFS('2. Private'!B:B,CRUSCOTTO!C9,'2. Private'!K:K,"-",'2. Private'!P:P,"Usata") -> 0 | N9: =COUNTIFS('2. Private'!B:B,CRUSCOTTO!C9,'2. Private'!K:K,"-",'2. Private'!P:P,"2a scelta") -> 0 | O9: =COUNTIFS('2. Private'!B:B,CRUSCOTTO!C9,'2. Private'!K:K,"-",'2. Private'!P:P,"Manca") -> 12 | P9: =IF(G9=0,"-",COUNTIFS('2. Private'!B:B,CRUSCOTTO!C9,'2. Private'!K:K,"Variante",'2. Private'!P:P,"Nuova")) -> 20 | Q9: =IF(G9=0,"-",COUNTIFS('2. Private'!B:B,CRUSCOTTO!C9,'2. Private'!K:K,"Variante",'2. Private'!P:P,"Usata")) -> 1 | R9: =IF(G9=0,"-",COUNTIFS('2. Private'!B:B,CRUSCOTTO!C9,'2. Private'!K:K,"Variante",'2. Private'!P:P,"2a scelta")) -> 0 | S9: =IF(G9=0,"-",COUNTIFS('2. Private'!B:B,CRUSCOTTO!C9,'2. Private'!K:K,"Variante",'2. Private'!P:P,"Manca")) -> 5 | U9: 2. Vaticano | W9: =COUNTIF('15. Vaticano'!A:A,"15. Vaticano") -> 334 | X9: =COUNTIF('15. Vaticano'!Q:Q,"Nuova")+COUNTIF('15. Vaticano'!Q:Q,"Usata")+COUNTIF('15. Vaticano'!Q:Q,"2a Scelta") -> 0 | Y9: =COUNTIF('15. Vaticano'!I:I,"Variante") -> 26 | Z9: =X9/W9 -> 0 | AA9: =COUNTIF('15. Vaticano'!Q:Q,"Manca") -> 334 | AB9: =SUM('15. Vaticano'!T:T) -> 0
C10: 3. Private Rese Pubbliche | E10: =IF(COUNTIF('2. Private'!B:B,CRUSCOTTO!C10)=(CRUSCOTTO!F10+CRUSCOTTO!G10),CRUSCOTTO!F10+CRUSCOTTO!G10,"Errore") -> 209 | F10: =COUNTIFS('2. Private'!B:B,CRUSCOTTO!C10,'2. Private'!K:K,"-") -> 198 | G10: =COUNTIFS('2. Private'!B:B,CRUSCOTTO!C10,'2. Private'!K:K,"Variante") -> 11 | H10: =(E10-I10)/E10 -> 0.99521531 | I10: =IF(G10=0,O10,O10+S10) -> 1 | J10: =SUMIF('2. Private'!B:B,CRUSCOTTO!C10,'2. Private'!T:T) -> 1203 | L10: =COUNTIFS('2. Private'!B:B,CRUSCOTTO!C10,'2. Private'!K:K,"-",'2. Private'!P:P,"Nuova") -> 198 | M10: =COUNTIFS('2. Private'!B:B,CRUSCOTTO!C10,'2. Private'!K:K,"-",'2. Private'!P:P,"Usata") -> 0 | N10: =COUNTIFS('2. Private'!B:B,CRUSCOTTO!C10,'2. Private'!K:K,"-",'2. Private'!P:P,"2a scelta") -> 0 | O10: =COUNTIFS('2. Private'!B:B,CRUSCOTTO!C10,'2. Private'!K:K,"-",'2. Private'!P:P,"Manca") -> 0 | P10: =IF(G10=0,"-",COUNTIFS('2. Private'!B:B,CRUSCOTTO!C10,'2. Private'!K:K,"Variante",'2. Private'!P:P,"Nuova")) -> 10 | Q10: =IF(G10=0,"-",COUNTIFS('2. Private'!B:B,CRUSCOTTO!C10,'2. Private'!K:K,"Variante",'2. Private'!P:P,"Usata")) -> 0 | R10: =IF(G10=0,"-",COUNTIFS('2. Private'!B:B,CRUSCOTTO!C10,'2. Private'!K:K,"Variante",'2. Private'!P:P,"2a scelta")) -> 0 | S10: =IF(G10=0,"-",COUNTIFS('2. Private'!B:B,CRUSCOTTO!C10,'2. Private'!K:K,"Variante",'2. Private'!P:P,"Manca")) -> 1 | T10: Infostrada | U10: 1. Ordinarie | V10: =W10+W11 -> 297 | W10: =COUNTIF('16. Infostrada'!B:B,U10) -> 48 | X10: =COUNTIFS('16. Infostrada'!B:B,U10,'16. Infostrada'!Q:Q,"Nuova")+COUNTIFS('16. Infostrada'!B:B,U10,'16. Infostrada'!Q:Q,"Usata")+COUNTIFS('16. Infostrada'!B:B,U10,'16. Infostrada'!Q:Q,"2a Scelta") -> 45 | Y10: =COUNTIFS('16. Infostrada'!B:B,U10,'16. Infostrada'!I:I,"Variante") -> 0 | Z10: =X10/W10 -> 0.9375 | AA10: =COUNTIFS('16. Infostrada'!B:B,U10,'16. Infostrada'!Q:Q,"Manca") -> 3 | AB10: =SUMIF('16. Infostrada'!B:B,CRUSCOTTO!U10,'16. Infostrada'!T:T) -> 42
B11: Ordinarie & Pubbliche Figurate | C11: 1. Fasce Orarie | D11: =SUM(E11:E16) -> 2922 | E11: =IF(COUNTIF('3. SIP'!B:B,CRUSCOTTO!C11)=(CRUSCOTTO!F11+CRUSCOTTO!G11),CRUSCOTTO!F11+CRUSCOTTO!G11,"Errore") -> 86 | F11: =COUNTIFS('3. SIP'!B:B,CRUSCOTTO!C11,'3. SIP'!K:K,"-") -> 65 | G11: =COUNTIFS('3. SIP'!B:B,CRUSCOTTO!C11,'3. SIP'!K:K,"Variante") -> 21 | H11: =(E11-I11)/E11 -> 0.96511628 | I11: =IF(G11=0,O11,O11+S11) -> 3 | J11: =SUMIF('3. SIP'!B:B,CRUSCOTTO!C11,'3. SIP'!T:T) -> 2206.8 | L11: =COUNTIFS('3. SIP'!B:B,CRUSCOTTO!C11,'3. SIP'!K:K,"-",'3. SIP'!P:P,"Nuova") -> 59 | M11: =COUNTIFS('3. SIP'!B:B,CRUSCOTTO!C11,'3. SIP'!K:K,"-",'3. SIP'!P:P,"Usata") -> 5 | N11: =COUNTIFS('3. SIP'!B:B,CRUSCOTTO!C11,'3. SIP'!K:K,"-",'3. SIP'!P:P,"2a scelta") -> 0 | O11: =COUNTIFS('3. SIP'!B:B,CRUSCOTTO!C11,'3. SIP'!K:K,"-",'3. SIP'!P:P,"Manca") -> 1 | P11: =COUNTIFS('3. SIP'!B:B,CRUSCOTTO!C11,'3. SIP'!K:K,"Variante",'3. SIP'!P:P,"Nuova") -> 18 | Q11: =COUNTIFS('3. SIP'!B:B,CRUSCOTTO!C11,'3. SIP'!K:K,"Variante",'3. SIP'!P:P,"Usata") -> 1 | R11: =COUNTIFS('3. SIP'!B:B,CRUSCOTTO!C11,'3. SIP'!K:K,"Variante",'3. SIP'!P:P,"2a scelta") -> 0 | S11: =COUNTIFS('3. SIP'!B:B,CRUSCOTTO!C11,'3. SIP'!K:K,"Variante",'3. SIP'!P:P,"Manca") -> 2 | U11: 2. Remote memory | W11: =COUNTIF('16. Infostrada'!B:B,U11) -> 249 | X11: =COUNTIFS('16. Infostrada'!B:B,U11,'16. Infostrada'!Q:Q,"Nuova")+COUNTIFS('16. Infostrada'!B:B,U11,'16. Infostrada'!Q:Q,"Usata")+COUNTIFS('16. Infostrada'!B:B,U11,'16. Infostrada'!Q:Q,"2a Scelta") -> 67 | Y11: =COUNTIFS('16. Infostrada'!B:B,U11,'16. Infostrada'!I:I,"Variante") -> 3 | Z11: =X11/W11 -> 0.26907631 | AA11: =COUNTIFS('16. Infostrada'!B:B,U11,'16. Infostrada'!Q:Q,"Manca") -> 182 | AB11: =SUMIF('16. Infostrada'!B:B,CRUSCOTTO!U11,'16. Infostrada'!T:T) -> 0
C12: 2. SIP | E12: =IF(COUNTIF('3. SIP'!B:B,CRUSCOTTO!C12)=(CRUSCOTTO!F12+CRUSCOTTO!G12),CRUSCOTTO!F12+CRUSCOTTO!G12,"Errore") -> 356 | F12: =COUNTIFS('3. SIP'!B:B,CRUSCOTTO!C12,'3. SIP'!K:K,"-") -> 335 | G12: =COUNTIFS('3. SIP'!B:B,CRUSCOTTO!C12,'3. SIP'!K:K,"Variante") -> 21 | H12: =(E12-I12)/E12 -> 0.99438202 | I12: =IF(G12=0,O12,O12+S12) -> 2 | J12: =SUMIF('3. SIP'!B:B,CRUSCOTTO!C12,'3. SIP'!T:T) -> 6639.65 | L12: =COUNTIFS('3. SIP'!B:B,CRUSCOTTO!C12,'3. SIP'!K:K,"-",'3. SIP'!P:P,"Nuova") -> 329 | M12: =COUNTIFS('3. SIP'!B:B,CRUSCOTTO!C12,'3. SIP'!K:K,"-",'3. SIP'!P:P,"Usata") -> 3 | N12: =COUNTIFS('3. SIP'!B:B,CRUSCOTTO!C12,'3. SIP'!K:K,"-",'3. SIP'!P:P,"2a scelta") -> 3 | O12: =COUNTIFS('3. SIP'!B:B,CRUSCOTTO!C12,'3. SIP'!K:K,"-",'3. SIP'!P:P,"Manca") -> 0 | P12: =COUNTIFS('3. SIP'!B:B,CRUSCOTTO!C12,'3. SIP'!K:K,"Variante",'3. SIP'!P:P,"Nuova") -> 17 | Q12: =COUNTIFS('3. SIP'!B:B,CRUSCOTTO!C12,'3. SIP'!K:K,"Variante",'3. SIP'!P:P,"Usata") -> 2 | R12: =COUNTIFS('3. SIP'!B:B,CRUSCOTTO!C12,'3. SIP'!K:K,"Variante",'3. SIP'!P:P,"2a scelta") -> 0 | S12: =COUNTIFS('3. SIP'!B:B,CRUSCOTTO!C12,'3. SIP'!K:K,"Variante",'3. SIP'!P:P,"Manca") -> 2 | T12: Albacom | U12: 1. Ordinarie | V12: =W12+W13 -> 214 | W12: =COUNTIF('17. Albacom'!B:B,U12) -> 13 | X12: =COUNTIFS('17. Albacom'!B:B,U12,'17. Albacom'!Q:Q,"Nuova")+COUNTIFS('17. Albacom'!B:B,U12,'17. Albacom'!Q:Q,"Usata")+COUNTIFS('17. Albacom'!B:B,U12,'17. Albacom'!Q:Q,"2a Scelta") -> 12 | Y12: =COUNTIFS('17. Albacom'!B:B,U12,'17. Albacom'!I:I,"Variante") -> 0 | Z12: =X12/W12 -> 0.92307692 | AA12: =COUNTIFS('17. Albacom'!B:B,U12,'17. Albacom'!Q:Q,"Manca") -> 1 | AB12: =SUMIF('17. Albacom'!B:B,CRUSCOTTO!U12,'17. Albacom'!T:T) -> 24
C13: 3. Telecom Lire | E13: =IF(COUNTIF('4. Telecom lire'!B:B,CRUSCOTTO!C13)=(CRUSCOTTO!F13+CRUSCOTTO!G13),CRUSCOTTO!F13+CRUSCOTTO!G13,"Errore") -> 1145 | F13: =COUNTIFS('4. Telecom lire'!B:B,CRUSCOTTO!C13,'4. Telecom lire'!K:K,"-") -> 1115 | G13: =COUNTIFS('4. Telecom lire'!B:B,CRUSCOTTO!C13,'4. Telecom lire'!K:K,"Variante") -> 30 | H13: =(E13-I13)/E13 -> 0.98340611 | I13: =IF(G13=0,O13,O13+S13) -> 19 | J13: =SUMIF('4. Telecom lire'!B:B,CRUSCOTTO!C13,'4. Telecom lire'!S:S) -> 2302.2 | L13: =COUNTIFS('4. Telecom lire'!B:B,CRUSCOTTO!C13,'4. Telecom lire'!K:K,"-",'4. Telecom lire'!P:P,"Nuova") -> 1112 | M13: =COUNTIFS('4. Telecom lire'!B:B,CRUSCOTTO!C13,'4. Telecom lire'!K:K,"-",'4. Telecom lire'!P:P,"Usata") -> 1 | N13: =COUNTIFS('4. Telecom lire'!B:B,CRUSCOTTO!C13,'4. Telecom lire'!K:K,"-",'4. Telecom lire'!P:P,"2a scelta") -> 0 | O13: =COUNTIFS('4. Telecom lire'!B:B,CRUSCOTTO!C13,'4. Telecom lire'!K:K,"-",'4. Telecom lire'!P:P,"Manca") -> 2 | P13: =COUNTIFS('4. Telecom lire'!B:B,CRUSCOTTO!C13,'4. Telecom lire'!K:K,"Variante",'4. Telecom lire'!P:P,"Nuova") -> 11 | Q13: =COUNTIFS('4. Telecom lire'!B:B,CRUSCOTTO!C13,'4. Telecom lire'!K:K,"Variante",'4. Telecom lire'!P:P,"Usata") -> 2 | R13: =COUNTIFS('4. Telecom lire'!B:B,CRUSCOTTO!C13,'4. Telecom lire'!K:K,"Variante",'4. Telecom lire'!P:P,"2a scelta") -> 0 | S13: =COUNTIFS('4. Telecom lire'!B:B,CRUSCOTTO!C13,'4. Telecom lire'!K:K,"Variante",'4. Telecom lire'!P:P,"Manca") -> 17 | U13: 2. Test, dimostrative, powered | W13: =COUNTIF('17. Albacom'!B:B,U13) -> 201 | X13: =COUNTIFS('17. Albacom'!B:B,U13,'17. Albacom'!Q:Q,"Nuova")+COUNTIFS('17. Albacom'!B:B,U13,'17. Albacom'!Q:Q,"Usata")+COUNTIFS('17. Albacom'!B:B,U13,'17. Albacom'!Q:Q,"2a Scelta") -> 15 | Y13: =COUNTIFS('17. Albacom'!B:B,U13,'17. Albacom'!I:I,"Variante") -> 0 | Z13: =X13/W13 -> 0.074626866 | AA13: =COUNTIFS('17. Albacom'!B:B,U13,'17. Albacom'!Q:Q,"Manca") -> 186 | AB13: =SUMIF('17. Albacom'!B:B,CRUSCOTTO!U13,'17. Albacom'!T:T) -> 0
C14: 4. Telecom Euro | E14: =IF(COUNTIF('5. Telecom euro'!B:B,CRUSCOTTO!C14)=(CRUSCOTTO!F14+CRUSCOTTO!G14),CRUSCOTTO!F14+CRUSCOTTO!G14,"Errore") -> 1131 | F14: =COUNTIFS('5. Telecom euro'!B:B,CRUSCOTTO!C14,'5. Telecom euro'!L:L,"-") -> 1129 | G14: =COUNTIFS('5. Telecom euro'!B:B,CRUSCOTTO!C14,'5. Telecom euro'!L:L,"Variante") -> 2 | H14: =(E14-I14)/E14 -> 0.99646331 | I14: =IF(G14=0,O14,O14+S14) -> 4 | J14: =SUMIF('5. Telecom euro'!B:B,CRUSCOTTO!C14,'5. Telecom euro'!T:T) -> 4063.2 | L14: =COUNTIFS('5. Telecom euro'!B:B,CRUSCOTTO!C14,'5. Telecom euro'!L:L,"-",'5. Telecom euro'!Q:Q,"Nuova") -> 1126 | M14: =COUNTIFS('5. Telecom euro'!B:B,CRUSCOTTO!C14,'5. Telecom euro'!L:L,"-",'5. Telecom euro'!Q:Q,"Usata") -> 0 | N14: =COUNTIFS('5. Telecom euro'!B:B,CRUSCOTTO!C14,'5. Telecom euro'!L:L,"-",'5. Telecom euro'!Q:Q,"2a scelta") -> 0 | O14: =COUNTIFS('5. Telecom euro'!B:B,CRUSCOTTO!C14,'5. Telecom euro'!L:L,"-",'5. Telecom euro'!Q:Q,"Manca") -> 3 | P14: =COUNTIFS('5. Telecom euro'!B:B,CRUSCOTTO!C14,'5. Telecom euro'!L:L,"Variante",'5. Telecom euro'!Q:Q,"Nuova") -> 1 | Q14: =COUNTIFS('5. Telecom euro'!B:B,CRUSCOTTO!C14,'5. Telecom euro'!L:L,"Variante",'5. Telecom euro'!Q:Q,"Usata") -> 0 | R14: =COUNTIFS('5. Telecom euro'!B:B,CRUSCOTTO!C14,'5. Telecom euro'!L:L,"Variante",'5. Telecom euro'!Q:Q,"2a scelta") -> 0 | S14: =COUNTIFS('5. Telecom euro'!B:B,CRUSCOTTO!C14,'5. Telecom euro'!L:L,"Variante",'5. Telecom euro'!Q:Q,"Manca") -> 1 | T14: Tiscali | U14: 1. Ordinarie | V14: =W14+W15 -> 877 | W14: =COUNTIF('18. Tiscali'!B:B,U14) -> 580 | X14: =COUNTIFS('18. Tiscali'!B:B,U14,'18. Tiscali'!Q:Q,"Nuova")+COUNTIFS('18. Tiscali'!B:B,U14,'18. Tiscali'!Q:Q,"Usata")+COUNTIFS('18. Tiscali'!B:B,U14,'18. Tiscali'!Q:Q,"2a Scelta") -> 0 | Y14: =COUNTIFS('18. Tiscali'!B:B,U14,'18. Tiscali'!I:I,"Variante") -> 260 | Z14: =X14/W14 -> 0 | AA14: =COUNTIFS('18. Tiscali'!B:B,U14,'18. Tiscali'!Q:Q,"Manca") -> 580 | AB14: =SUMIF('18. Tiscali'!B:B,CRUSCOTTO!U14,'18. Tiscali'!T:T) -> 0
C15: 5. Alto Adige | E15: =IF(COUNTIF('6. Alto Adige'!B:B,CRUSCOTTO!C15)=(CRUSCOTTO!F15+CRUSCOTTO!G15),CRUSCOTTO!F15+CRUSCOTTO!G15,"Errore") -> 162 | F15: =COUNTIFS('6. Alto Adige'!B:B,CRUSCOTTO!C15,'6. Alto Adige'!K:K,"-") -> 155 | G15: =COUNTIFS('6. Alto Adige'!B:B,CRUSCOTTO!C15,'6. Alto Adige'!K:K,"Variante") -> 7 | H15: =(E15-I15)/E15 -> 0.95061728 | I15: =IF(G15=0,O15,O15+S15) -> 8 | J15: =SUMIF('6. Alto Adige'!B:B,CRUSCOTTO!C15,'6. Alto Adige'!T:T) -> 3239.2 | L15: =COUNTIFS('6. Alto Adige'!B:B,CRUSCOTTO!C15,'6. Alto Adige'!K:K,"-",'6. Alto Adige'!P:P,"Nuova") -> 145 | M15: =COUNTIFS('6. Alto Adige'!B:B,CRUSCOTTO!C15,'6. Alto Adige'!K:K,"-",'6. Alto Adige'!P:P,"Usata") -> 4 | N15: =COUNTIFS('6. Alto Adige'!B:B,CRUSCOTTO!C15,'6. Alto Adige'!K:K,"-",'6. Alto Adige'!P:P,"2a scelta") -> 0 | O15: =COUNTIFS('6. Alto Adige'!B:B,CRUSCOTTO!C15,'6. Alto Adige'!K:K,"-",'6. Alto Adige'!P:P,"Manca") -> 6 | P15: =COUNTIFS('6. Alto Adige'!B:B,CRUSCOTTO!C15,'6. Alto Adige'!K:K,"Variante",'6. Alto Adige'!P:P,"Nuova") -> 4 | Q15: =COUNTIFS('6. Alto Adige'!B:B,CRUSCOTTO!C15,'6. Alto Adige'!K:K,"Variante",'6. Alto Adige'!P:P,"Usata") -> 1 | R15: =COUNTIFS('6. Alto Adige'!B:B,CRUSCOTTO!C15,'6. Alto Adige'!K:K,"Variante",'6. Alto Adige'!P:P,"2a scelta") -> 0 | S15: =COUNTIFS('6. Alto Adige'!B:B,CRUSCOTTO!C15,'6. Alto Adige'!K:K,"Variante",'6. Alto Adige'!P:P,"Manca") -> 2 | U15: 2. Ricaricasa, Netcard | W15: =COUNTIF('18. Tiscali'!B:B,U15) -> 297 | X15: =COUNTIFS('18. Tiscali'!B:B,U15,'18. Tiscali'!Q:Q,"Nuova")+COUNTIFS('18. Tiscali'!B:B,U15,'18. Tiscali'!Q:Q,"Usata")+COUNTIFS('18. Tiscali'!B:B,U15,'18. Tiscali'!Q:Q,"2a Scelta") -> 0 | Y15: =COUNTIFS('18. Tiscali'!B:B,U15,'18. Tiscali'!I:I,"Variante") -> 133 | Z15: =X15/W15 -> 0 | AA15: =COUNTIFS('18. Tiscali'!B:B,U15,'18. Tiscali'!Q:Q,"Manca") -> 297 | AB15: =SUMIF('18. Tiscali'!B:B,CRUSCOTTO!U15,'18. Tiscali'!T:T) -> 0
C16: 6. Basi militari | E16: =IF(COUNTIF('7. Basi Militari'!B:B,CRUSCOTTO!C16)=(CRUSCOTTO!F16+CRUSCOTTO!G16),CRUSCOTTO!F16+CRUSCOTTO!G16,"Errore") -> 42 | F16: =COUNTIFS('7. Basi Militari'!B:B,CRUSCOTTO!C16,'7. Basi Militari'!L:L,"-") -> 31 | G16: =COUNTIFS('7. Basi Militari'!B:B,CRUSCOTTO!C16,'7. Basi Militari'!L:L,"Varietà") -> 11 | H16: =(E16-I16)/E16 -> 0.85714286 | I16: =IF(G16=0,O16,O16+S16) -> 6 | J16: =SUMIF('1. Precursorie'!B:B,CRUSCOTTO!C16,'1. Precursorie'!S:S) -> 0 | L16: =COUNTIFS('7. Basi Militari'!B:B,CRUSCOTTO!C16,'7. Basi Militari'!L:L,"-",'7. Basi Militari'!Q:Q,"Nuova") -> 1 | M16: =COUNTIFS('7. Basi Militari'!B:B,CRUSCOTTO!C16,'7. Basi Militari'!L:L,"-",'7. Basi Militari'!Q:Q,"Usata") -> 29 | N16: =COUNTIFS('7. Basi Militari'!B:B,CRUSCOTTO!C16,'7. Basi Militari'!L:L,"-",'7. Basi Militari'!Q:Q,"2a Scelta") -> 0 | O16: =COUNTIFS('7. Basi Militari'!B:B,CRUSCOTTO!C16,'7. Basi Militari'!L:L,"-",'7. Basi Militari'!Q:Q,"Manca") -> 1 | P16: =COUNTIFS('7. Basi Militari'!B:B,CRUSCOTTO!C16,'7. Basi Militari'!L:L,"Varietà",'7. Basi Militari'!Q:Q,"Nuova") -> 0 | Q16: =COUNTIFS('7. Basi Militari'!B:B,CRUSCOTTO!C16,'7. Basi Militari'!L:L,"Varietà",'7. Basi Militari'!Q:Q,"Usata") -> 6 | R16: =COUNTIFS('7. Basi Militari'!B:B,CRUSCOTTO!C16,'7. Basi Militari'!L:L,"Varietà",'7. Basi Militari'!Q:Q,"2a Scelta") -> 0 | S16: =COUNTIFS('7. Basi Militari'!B:B,CRUSCOTTO!C16,'7. Basi Militari'!L:L,"Varietà",'7. Basi Militari'!Q:Q,"Manca") -> 5 | T16: ATW | U16: 1. Ordinarie | V16: =W16+W17 -> 367 | W16: =COUNTIF('19. ATW'!B:B,U16) -> 356 | X16: =COUNTIFS('19. ATW'!B:B,U16,'19. ATW'!Q:Q,"Nuova")+COUNTIFS('19. ATW'!B:B,U16,'19. ATW'!Q:Q,"Usata")+COUNTIFS('19. ATW'!B:B,U16,'19. ATW'!Q:Q,"2a Scelta") -> 215 | Y16: =COUNTIFS('19. ATW'!B:B,U16,'19. ATW'!I:I,"Variante") -> 16 | Z16: =X16/W16 -> 0.60393258 | AA16: =COUNTIFS('19. ATW'!B:B,U16,'19. ATW'!Q:Q,"Manca") -> 141 | AB16: =SUMIF('19. ATW'!B:B,CRUSCOTTO!U16,'19. ATW'!T:T) -> 770
E17: =SUM(E4:E16) -> 3688 | F17: =SUM(F4:F16) -> 3481 | G17: =SUM(G4:G16) -> 207 | H17: =(E17-I17)/E17 -> 0.96908894 | I17: =SUM(I4:I16) -> 114 | J17: =SUM(J4:J16) -> 41047.55 | L17: =SUM(L4:L16)/$F$17 -> 0.94484344 | M17: =SUM(M4:M16)/$F$17 -> 0.036483769 | N17: =SUM(N4:N16)/$F$17 -> 0.0020109164 | O17: =SUM(O4:O16)/$F$17 -> 0.016661879 | P17: =SUM(P4:P16)/$G$17 -> 0.52173913 | Q17: =SUM(Q4:Q16)/$G$17 -> 0.19806763 | R17: =SUM(R4:R16)/$G$17 -> 0.0096618357 | S17: =SUM(S4:S16)/$G$17 -> 0.2705314 | U17: 2. Test, Sample, Promocard | W17: =COUNTIF('19. ATW'!B:B,U17) -> 11 | X17: =COUNTIFS('19. ATW'!B:B,U17,'19. ATW'!Q:Q,"Nuova")+COUNTIFS('19. ATW'!B:B,U17,'19. ATW'!Q:Q,"Usata")+COUNTIFS('19. ATW'!B:B,U17,'19. ATW'!Q:Q,"2a Scelta") -> 8 | Y17: =COUNTIFS('19. ATW'!B:B,U17,'19. ATW'!I:I,"Variante") -> 0 | Z17: =X17/W17 -> 0.72727273 | AA17: =COUNTIFS('19. ATW'!B:B,U17,'19. ATW'!Q:Q,"Manca") -> 3 | AB17: =SUMIF('19. ATW'!B:B,CRUSCOTTO!U17,'19. ATW'!T:T) -> 63
T18: Altre compagnie | U18: 20. Accesso web | V18: =SUM(W18:W23) -> 335 | W18: =COUNTIF('20. Accesso Web'!A:A,U18) -> 170 | X18: =COUNTIFS('20. Accesso Web'!A:A,U18,'20. Accesso Web'!Q:Q,"Nuova")+COUNTIFS('20. Accesso Web'!A:A,U18,'20. Accesso Web'!Q:Q,"Usata")+COUNTIFS('20. Accesso Web'!A:A,U18,'20. Accesso Web'!Q:Q,"2a Scelta") -> 0 | Y18: =COUNTIFS('20. Accesso Web'!A:A,U18,'20. Accesso Web'!I:I,"Variante") -> 4 | Z18: =X18/W18 -> 0 | AA18: =COUNTIFS('20. Accesso Web'!A:A,U18,'20. Accesso Web'!Q:Q,"Manca") -> 170 | AB18: =SUMIF('20. Accesso Web'!A:A,CRUSCOTTO!U18,'20. Accesso Web'!T:T) -> 0
B19: Genere | C19: Sottogenere | D19: # TOT schede | F19: # In collezione | G19: # Varianti | H19: Avanzamento | I19: # Mancanti | J19: Valore G26 | L19: Presente | M19: Mancante | N19: Presente | O19: Mancanti | U19: 21. Adriacom | W19: =COUNTIF('21. Adriacom'!B:B,U19) -> 29 | X19: =COUNTIFS('21. Adriacom'!B:B,U19,'21. Adriacom'!Q:Q,"Nuova")+COUNTIFS('21. Adriacom'!B:B,U19,'21. Adriacom'!Q:Q,"Usata")+COUNTIFS('21. Adriacom'!B:B,U19,'21. Adriacom'!Q:Q,"2a Scelta") -> 0 | Y19: =COUNTIFS('21. Adriacom'!B:B,U19,'21. Adriacom'!I:I,"Variante") -> 0 | Z19: =X19/W19 -> 0 | AA19: =COUNTIFS('21. Adriacom'!B:B,U19,'21. Adriacom'!Q:Q,"Manca") -> 29 | AB19: =SUMIF('20. Accesso Web'!A:A,CRUSCOTTO!U19,'20. Accesso Web'!T:T) -> 0
M20: =COUNTIFS('8. Folder'!B:B,CRUSCOTTO!U27,'8. Folder'!J:J,"-",'8. Folder'!M:M,"Sì") -> 12 | N20: =COUNTIFS('8. Folder'!B:B,CRUSCOTTO!U27,'8. Folder'!J:J,"-",'8. Folder'!M:M,"No") -> 10 | O20: =IF(Y27=0,"-",COUNTIFS('8. Folder'!B:B,CRUSCOTTO!U27,'8. Folder'!J:J,"Variante",'8. Folder'!M:M,"Sì")) -> - | P20: =IF(Y27=0,"-",COUNTIFS('8. Folder'!B:B,CRUSCOTTO!U27,'8. Folder'!J:J,"Variante",'8. Folder'!M:M,"No")) -> - | U20: 22. Noicom | W20: =COUNTIF('21. Adriacom'!B:B,U20) -> 17 | X20: =COUNTIFS('21. Adriacom'!B:B,U20,'21. Adriacom'!Q:Q,"Nuova")+COUNTIFS('21. Adriacom'!B:B,U20,'21. Adriacom'!Q:Q,"Usata")+COUNTIFS('21. Adriacom'!B:B,U20,'21. Adriacom'!Q:Q,"2a Scelta") -> 0 | Y20: =COUNTIFS('21. Adriacom'!B:B,U20,'21. Adriacom'!I:I,"Variante") -> 0 | Z20: =X20/W20 -> 0 | AA20: =COUNTIFS('21. Adriacom'!B:B,U20,'21. Adriacom'!Q:Q,"Manca") -> 17 | AB20: =SUMIF('20. Accesso Web'!A:A,CRUSCOTTO!U20,'20. Accesso Web'!T:T) -> 0
B21: Prototipi | C21: 1. Sida | D21: =SUM(E21:E30) -> 784 | E21: =COUNTIF('11. Prototipi'!B:B,CRUSCOTTO!C21) -> 36 | F21: =COUNTIFS('11. Prototipi'!B:B,CRUSCOTTO!C21,'11. Prototipi'!U:U,"Nuova")+COUNTIFS('11. Prototipi'!B:B,CRUSCOTTO!C21,'11. Prototipi'!U:U,"Usata")+COUNTIFS('11. Prototipi'!U:U,CRUSCOTTO!C21,'11. Prototipi'!U:U,"2a Scelta") -> 2 | G21: - | H21: =(F21)/E21 -> 0.055555556 | I21: =COUNTIFS('11. Prototipi'!B:B,C21,'11. Prototipi'!U:U,"Manca") -> 34 | J21: =SUMIF('11. Prototipi'!B:B,CRUSCOTTO!C21,'11. Prototipi'!X:X) -> 150 | M21: =COUNTIFS('8. Folder'!B:B,CRUSCOTTO!U28,'8. Folder'!J:J,"-",'8. Folder'!M:M,"Sì") -> 23 | N21: =COUNTIFS('8. Folder'!B:B,CRUSCOTTO!U28,'8. Folder'!J:J,"-",'8. Folder'!M:M,"No") -> 8 | O21: =IF(Y28=0,"-",COUNTIFS('8. Folder'!B:B,CRUSCOTTO!U28,'8. Folder'!J:J,"Variante",'8. Folder'!M:M,"Sì")) -> - | P21: =IF(Y28=0,"-",COUNTIFS('8. Folder'!B:B,CRUSCOTTO!U28,'8. Folder'!J:J,"Variante",'8. Folder'!M:M,"No")) -> - | U21: 23. Intelcom / Westel | W21: =COUNTIF('20. Accesso Web'!A:A,U21) -> 0 | X21: =COUNTIFS('20. Accesso Web'!A:A,U21,'20. Accesso Web'!Q:Q,"Nuova")+COUNTIFS('20. Accesso Web'!A:A,U21,'20. Accesso Web'!Q:Q,"Usata")+COUNTIFS('20. Accesso Web'!A:A,U21,'20. Accesso Web'!Q:Q,"2a Scelta") -> 0 | Y21: =COUNTIFS('20. Accesso Web'!A:A,U21,'20. Accesso Web'!I:I,"Variante") -> 0 | Z21: =X21/W21 -> #DIV/0! | AA21: =COUNTIFS('20. Accesso Web'!A:A,U21,'20. Accesso Web'!Q:Q,"Manca") -> 0 | AB21: =SUMIF('20. Accesso Web'!A:A,CRUSCOTTO!U21,'20. Accesso Web'!T:T) -> 0
C22: 2. Appalto | E22: =COUNTIF('11. Prototipi'!B:B,CRUSCOTTO!C22) -> 56 | F22: =COUNTIFS('11. Prototipi'!B:B,CRUSCOTTO!C22,'11. Prototipi'!U:U,"Nuova")+COUNTIFS('11. Prototipi'!B:B,CRUSCOTTO!C22,'11. Prototipi'!U:U,"Usata")+COUNTIFS('11. Prototipi'!U:U,CRUSCOTTO!C22,'11. Prototipi'!U:U,"2a Scelta") -> 4 | G22: - | H22: =(F22)/E22 -> 0.071428571 | I22: =COUNTIFS('11. Prototipi'!B:B,C22,'11. Prototipi'!U:U,"Manca") -> 52 | J22: =SUMIF('11. Prototipi'!B:B,CRUSCOTTO!C22,'11. Prototipi'!X:X) -> 190 | M22: =COUNTIFS('8. Folder'!B:B,CRUSCOTTO!U29,'8. Folder'!J:J,"-",'8. Folder'!M:M,"Sì") -> 83 | N22: =COUNTIFS('8. Folder'!B:B,CRUSCOTTO!U29,'8. Folder'!J:J,"-",'8. Folder'!M:M,"No") -> 11 | O22: =IF(Y29=0,"-",COUNTIFS('8. Folder'!B:B,CRUSCOTTO!U29,'8. Folder'!J:J,"Variante",'8. Folder'!M:M,"Sì")) -> 3 | P22: =IF(Y29=0,"-",COUNTIFS('8. Folder'!B:B,CRUSCOTTO!U29,'8. Folder'!J:J,"Variante",'8. Folder'!M:M,"No")) -> 0 | U22: 24. RSLCom | W22: =COUNTIF('20. Accesso Web'!A:A,U22) -> 0 | X22: =COUNTIFS('20. Accesso Web'!A:A,U22,'20. Accesso Web'!Q:Q,"Nuova")+COUNTIFS('20. Accesso Web'!A:A,U22,'20. Accesso Web'!Q:Q,"Usata")+COUNTIFS('20. Accesso Web'!A:A,U22,'20. Accesso Web'!Q:Q,"2a Scelta") -> 0 | Y22: =COUNTIFS('20. Accesso Web'!A:A,U22,'20. Accesso Web'!I:I,"Variante") -> 0 | Z22: =X22/W22 -> #DIV/0! | AA22: =COUNTIFS('20. Accesso Web'!A:A,U22,'20. Accesso Web'!Q:Q,"Manca") -> 0 | AB22: =SUMIF('20. Accesso Web'!A:A,CRUSCOTTO!U22,'20. Accesso Web'!T:T) -> 0
C23: 3. Urmet | E23: =COUNTIF('11. Prototipi'!B:B,CRUSCOTTO!C23) -> 55 | F23: =COUNTIFS('11. Prototipi'!B:B,CRUSCOTTO!C23,'11. Prototipi'!U:U,"Nuova")+COUNTIFS('11. Prototipi'!B:B,CRUSCOTTO!C23,'11. Prototipi'!U:U,"Usata")+COUNTIFS('11. Prototipi'!U:U,CRUSCOTTO!C23,'11. Prototipi'!U:U,"2a Scelta") -> 28 | G23: - | H23: =(F23)/E23 -> 0.50909091 | I23: =COUNTIFS('11. Prototipi'!B:B,C23,'11. Prototipi'!U:U,"Manca") -> 27 | J23: =SUMIF('11. Prototipi'!B:B,CRUSCOTTO!C23,'11. Prototipi'!X:X) -> 1371 | M23: =COUNTIFS('8. Folder'!B:B,CRUSCOTTO!U30,'8. Folder'!J:J,"-",'8. Folder'!M:M,"Sì") -> 11 | N23: =COUNTIFS('8. Folder'!B:B,CRUSCOTTO!U30,'8. Folder'!J:J,"-",'8. Folder'!M:M,"No") -> 2 | O23: =IF(Y30=0,"-",COUNTIFS('8. Folder'!B:B,CRUSCOTTO!U30,'8. Folder'!J:J,"Variante",'8. Folder'!M:M,"Sì")) -> - | P23: =IF(Y30=0,"-",COUNTIFS('8. Folder'!B:B,CRUSCOTTO!U30,'8. Folder'!J:J,"Variante",'8. Folder'!M:M,"No")) -> - | U23: 25. Arcard / TCP | W23: =COUNTIF('25. Arcard TCP'!A:A,U23) -> 119 | X23: =COUNTIF('25. Arcard TCP'!Q:Q,"Nuova")+COUNTIF('25. Arcard TCP'!Q:Q,"Usata")+COUNTIF('25. Arcard TCP'!Q:Q,"2a Scelta") -> 80 | Y23: =COUNTIFS('25. Arcard TCP'!A:A,U23,'25. Arcard TCP'!I:I,"Variante") -> 0 | Z23: =X23/W23 -> 0.67226891 | AA23: =COUNTIF('25. Arcard TCP'!Q:Q,"Manca") -> 33 | AB23: =SUMIF('20. Accesso Web'!A:A,CRUSCOTTO!U23,'20. Accesso Web'!T:T) -> 0
C24: 4. Fasce orarie | E24: =COUNTIF('11. Prototipi'!B:B,CRUSCOTTO!C24) -> 34 | F24: =COUNTIFS('11. Prototipi'!B:B,CRUSCOTTO!C24,'11. Prototipi'!U:U,"Nuova")+COUNTIFS('11. Prototipi'!B:B,CRUSCOTTO!C24,'11. Prototipi'!U:U,"Usata")+COUNTIFS('11. Prototipi'!U:U,CRUSCOTTO!C24,'11. Prototipi'!U:U,"2a Scelta") -> 10 | G24: - | H24: =(F24)/E24 -> 0.29411765 | I24: =COUNTIFS('11. Prototipi'!B:B,C24,'11. Prototipi'!U:U,"Manca") -> 24 | J24: =SUMIF('11. Prototipi'!B:B,CRUSCOTTO!C24,'11. Prototipi'!X:X) -> 713 | M24: =COUNTIFS('8. Folder'!B:B,CRUSCOTTO!U31,'8. Folder'!J:J,"-",'8. Folder'!M:M,"Sì") -> 206 | N24: =COUNTIFS('8. Folder'!B:B,CRUSCOTTO!U31,'8. Folder'!J:J,"-",'8. Folder'!M:M,"No") -> 35 | O24: =IF(Y31=0,"-",COUNTIFS('8. Folder'!B:B,CRUSCOTTO!U31,'8. Folder'!J:J,"Variante",'8. Folder'!M:M,"Sì")) -> 6 | P24: =IF(Y31=0,"-",COUNTIFS('8. Folder'!B:B,CRUSCOTTO!U31,'8. Folder'!J:J,"Variante",'8. Folder'!M:M,"No")) -> 6 | W24: =SUM(W4:W23) -> 3390 | X24: =SUM(X4:X23) -> 889 | Y24: - | Z24: =(W24-AA24)/W24 -> 0.35103245 | AA24: =SUM(AA4:AA23) -> 2200 | AB24: =SUM(AB4:AB23) -> 2751.5
C25: 5. SIP | E25: =COUNTIF('11. Prototipi'!B:B,CRUSCOTTO!C25) -> 182 | F25: =COUNTIFS('11. Prototipi'!B:B,CRUSCOTTO!C25,'11. Prototipi'!U:U,"Nuova")+COUNTIFS('11. Prototipi'!B:B,CRUSCOTTO!C25,'11. Prototipi'!U:U,"Usata")+COUNTIFS('11. Prototipi'!U:U,CRUSCOTTO!C25,'11. Prototipi'!U:U,"2a Scelta") -> 35 | G25: - | H25: =(F25)/E25 -> 0.19230769 | I25: =COUNTIFS('11. Prototipi'!B:B,C25,'11. Prototipi'!U:U,"Manca") -> 147 | J25: =SUMIF('11. Prototipi'!B:B,CRUSCOTTO!C25,'11. Prototipi'!X:X) -> 1359 | M25: =COUNTIFS('8. Folder'!B:B,CRUSCOTTO!U32,'8. Folder'!J:J,"-",'8. Folder'!M:M,"Sì") -> 99 | N25: =COUNTIFS('8. Folder'!B:B,CRUSCOTTO!U32,'8. Folder'!J:J,"-",'8. Folder'!M:M,"No") -> 2 | O25: =IF(Y32=0,"-",COUNTIFS('8. Folder'!B:B,CRUSCOTTO!U32,'8. Folder'!J:J,"Variante",'8. Folder'!M:M,"Sì")) -> 2 | P25: =IF(Y32=0,"-",COUNTIFS('8. Folder'!B:B,CRUSCOTTO!U32,'8. Folder'!J:J,"Variante",'8. Folder'!M:M,"No")) -> 3
C26: 6. Telecom | E26: =COUNTIF('11. Prototipi'!B:B,CRUSCOTTO!C26) -> 163 | F26: =COUNTIFS('11. Prototipi'!B:B,CRUSCOTTO!C26,'11. Prototipi'!U:U,"Nuova")+COUNTIFS('11. Prototipi'!B:B,CRUSCOTTO!C26,'11. Prototipi'!U:U,"Usata")+COUNTIFS('11. Prototipi'!U:U,CRUSCOTTO!C26,'11. Prototipi'!U:U,"2a Scelta") -> 72 | G26: - | H26: =(F26)/E26 -> 0.44171779 | I26: =COUNTIFS('11. Prototipi'!B:B,C26,'11. Prototipi'!U:U,"Manca") -> 91 | J26: =SUMIF('11. Prototipi'!B:B,CRUSCOTTO!C26,'11. Prototipi'!X:X) -> 937 | M26: =COUNTIFS('8. Folder'!B:B,CRUSCOTTO!U33,'8. Folder'!J:J,"-",'8. Folder'!M:M,"Sì") -> 30 | N26: =COUNTIFS('8. Folder'!B:B,CRUSCOTTO!U33,'8. Folder'!J:J,"-",'8. Folder'!M:M,"No") -> 0 | O26: =IF(Y33=0,"-",COUNTIFS('8. Folder'!B:B,CRUSCOTTO!U33,'8. Folder'!J:J,"Variante",'8. Folder'!M:M,"Sì")) -> - | P26: =IF(Y33=0,"-",COUNTIFS('8. Folder'!B:B,CRUSCOTTO!U33,'8. Folder'!J:J,"Variante",'8. Folder'!M:M,"No")) -> - | T26: Genere | U26: Sottogenere | V26: # TOT Folder | X26: # Ordinari | Y26: # Varianti | Z26: Avanzamento | AA26: # Mancanti | AB26: Valore G25
C27: 7. Chip | E27: =COUNTIF('11. Prototipi'!B:B,CRUSCOTTO!C27) -> 21 | F27: =COUNTIFS('11. Prototipi'!B:B,CRUSCOTTO!C27,'11. Prototipi'!U:U,"Nuova")+COUNTIFS('11. Prototipi'!B:B,CRUSCOTTO!C27,'11. Prototipi'!U:U,"Usata")+COUNTIFS('11. Prototipi'!U:U,CRUSCOTTO!C27,'11. Prototipi'!U:U,"2a Scelta") -> 2 | G27: - | H27: =(F27)/E27 -> 0.095238095 | I27: =COUNTIFS('11. Prototipi'!B:B,C27,'11. Prototipi'!U:U,"Manca") -> 19 | J27: =SUMIF('11. Prototipi'!B:B,CRUSCOTTO!C27,'11. Prototipi'!X:X) -> 270 | M27: =COUNTIFS('8. Folder'!B:B,CRUSCOTTO!U34,'8. Folder'!J:J,"-",'8. Folder'!M:M,"Sì") -> 3 | N27: =COUNTIFS('8. Folder'!B:B,CRUSCOTTO!U34,'8. Folder'!J:J,"-",'8. Folder'!M:M,"No") -> 0 | O27: =IF(Y34=0,"-",COUNTIFS('8. Folder'!B:B,CRUSCOTTO!U34,'8. Folder'!J:J,"Variante",'8. Folder'!M:M,"Sì")) -> - | P27: =IF(Y34=0,"-",COUNTIFS('8. Folder'!B:B,CRUSCOTTO!U34,'8. Folder'!J:J,"Variante",'8. Folder'!M:M,"No")) -> - | T27: Folder | U27: 1. Precursorie omaggio | V27: =SUM(W27:W29) -> 150 | W27: =IF(COUNTIF('8. Folder'!B:B,CRUSCOTTO!U27)=(CRUSCOTTO!X27+CRUSCOTTO!Y27),CRUSCOTTO!X27+CRUSCOTTO!Y27,"Errore") -> 22 | X27: =COUNTIFS('8. Folder'!B:B,CRUSCOTTO!U27,'8. Folder'!J:J,"-") -> 22 | Y27: =COUNTIFS('8. Folder'!B:B,CRUSCOTTO!U27,'8. Folder'!J:J,"Variante") -> 0 | Z27: =(W27-AA27)/W27 -> 0.54545455 | AA27: =IF(Y27=0,N20,N20+P20) -> 10 | AB27: =SUMIF('8. Folder'!B:B,CRUSCOTTO!U27,'8. Folder'!P:P) -> 169
C28: 8. IPM-Incard | E28: =COUNTIF('11. Prototipi'!B:B,CRUSCOTTO!C28) -> 107 | F28: =COUNTIFS('11. Prototipi'!B:B,CRUSCOTTO!C28,'11. Prototipi'!U:U,"Nuova")+COUNTIFS('11. Prototipi'!B:B,CRUSCOTTO!C28,'11. Prototipi'!U:U,"Usata")+COUNTIFS('11. Prototipi'!U:U,CRUSCOTTO!C28,'11. Prototipi'!U:U,"2a Scelta") -> 28 | G28: - | H28: =(F28)/E28 -> 0.26168224 | I28: =COUNTIFS('11. Prototipi'!B:B,C28,'11. Prototipi'!U:U,"Manca") -> 79 | J28: =SUMIF('11. Prototipi'!B:B,CRUSCOTTO!C28,'11. Prototipi'!X:X) -> 1077 | M28: =COUNTIFS('8. Folder'!B:B,CRUSCOTTO!U35,'8. Folder'!J:J,"-",'8. Folder'!M:M,"Sì") -> 1 | N28: =COUNTIFS('8. Folder'!B:B,CRUSCOTTO!U35,'8. Folder'!J:J,"-",'8. Folder'!M:M,"No") -> 1 | O28: =IF(Y35=0,"-",COUNTIFS('8. Folder'!B:B,CRUSCOTTO!U35,'8. Folder'!J:J,"Variante",'8. Folder'!M:M,"Sì")) -> - | P28: =IF(Y35=0,"-",COUNTIFS('8. Folder'!B:B,CRUSCOTTO!U35,'8. Folder'!J:J,"Variante",'8. Folder'!M:M,"No")) -> - | U28: 2. Omaggio private | W28: =IF(COUNTIF('8. Folder'!B:B,CRUSCOTTO!U28)=(CRUSCOTTO!X28+CRUSCOTTO!Y28),CRUSCOTTO!X28+CRUSCOTTO!Y28,"Errore") -> 31 | X28: =COUNTIFS('8. Folder'!B:B,CRUSCOTTO!U28,'8. Folder'!J:J,"-") -> 31 | Y28: =COUNTIFS('8. Folder'!B:B,CRUSCOTTO!U28,'8. Folder'!J:J,"Variante") -> 0 | Z28: =(W28-AA28)/W28 -> 0.74193548 | AA28: =IF(Y28=0,N21,N21+P21) -> 8 | AB28: =SUMIF('8. Folder'!B:B,CRUSCOTTO!U28,'8. Folder'!P:P) -> 655
C29: 9. Urmet | E29: =COUNTIF('11. Prototipi'!B:B,CRUSCOTTO!C29) -> 110 | F29: =COUNTIFS('11. Prototipi'!B:B,CRUSCOTTO!C29,'11. Prototipi'!U:U,"Nuova")+COUNTIFS('11. Prototipi'!B:B,CRUSCOTTO!C29,'11. Prototipi'!U:U,"Usata")+COUNTIFS('11. Prototipi'!U:U,CRUSCOTTO!C29,'11. Prototipi'!U:U,"2a Scelta") -> 53 | G29: - | H29: =(F29)/E29 -> 0.48181818 | I29: =COUNTIFS('11. Prototipi'!B:B,C29,'11. Prototipi'!U:U,"Manca") -> 57 | J29: =SUMIF('11. Prototipi'!B:B,CRUSCOTTO!C29,'11. Prototipi'!X:X) -> 697 | M29: =COUNTIFS('8. Folder'!B:B,CRUSCOTTO!U36,'8. Folder'!J:J,"-",'8. Folder'!M:M,"Sì") -> 7 | N29: =COUNTIFS('8. Folder'!B:B,CRUSCOTTO!U36,'8. Folder'!J:J,"-",'8. Folder'!M:M,"No") -> 2 | O29: =IF(Y36=0,"-",COUNTIFS('8. Folder'!B:B,CRUSCOTTO!U36,'8. Folder'!J:J,"Variante",'8. Folder'!M:M,"Sì")) -> - | P29: =IF(Y36=0,"-",COUNTIFS('8. Folder'!B:B,CRUSCOTTO!U36,'8. Folder'!J:J,"Variante",'8. Folder'!M:M,"No")) -> - | U29: 3. Private Rese Pubbliche | W29: =IF(COUNTIF('8. Folder'!B:B,CRUSCOTTO!U29)=(CRUSCOTTO!X29+CRUSCOTTO!Y29),CRUSCOTTO!X29+CRUSCOTTO!Y29,"Errore") -> 97 | X29: =COUNTIFS('8. Folder'!B:B,CRUSCOTTO!U29,'8. Folder'!J:J,"-") -> 94 | Y29: =COUNTIFS('8. Folder'!B:B,CRUSCOTTO!U29,'8. Folder'!J:J,"Variante") -> 3 | Z29: =(W29-AA29)/W29 -> 0.88659794 | AA29: =IF(Y29=0,N22,N22+P22) -> 11 | AB29: =SUMIF('8. Folder'!B:B,CRUSCOTTO!U29,'8. Folder'!P:P) -> 1104
C30: 10. Prove materiale | E30: =COUNTIF('11. Prototipi'!B:B,CRUSCOTTO!C30) -> 20 | F30: =COUNTIFS('11. Prototipi'!B:B,CRUSCOTTO!C30,'11. Prototipi'!U:U,"Nuova")+COUNTIFS('11. Prototipi'!B:B,CRUSCOTTO!C30,'11. Prototipi'!U:U,"Usata")+COUNTIFS('11. Prototipi'!U:U,CRUSCOTTO!C30,'11. Prototipi'!U:U,"2a Scelta") -> 8 | G30: - | H30: =(F30)/E30 -> 0.4 | I30: =COUNTIFS('11. Prototipi'!B:B,C30,'11. Prototipi'!U:U,"Manca") -> 12 | J30: =SUMIF('11. Prototipi'!B:B,CRUSCOTTO!C30,'11. Prototipi'!X:X) -> 115 | M30: =COUNTIFS('8. Folder'!B:B,CRUSCOTTO!U37,'8. Folder'!J:J,"-",'8. Folder'!M:M,"Sì") -> 36 | N30: =COUNTIFS('8. Folder'!B:B,CRUSCOTTO!U37,'8. Folder'!J:J,"-",'8. Folder'!M:M,"No") -> 18 | O30: =IF(Y37=0,"-",COUNTIFS('8. Folder'!B:B,CRUSCOTTO!U37,'8. Folder'!J:J,"Variante",'8. Folder'!M:M,"Sì")) -> - | P30: =IF(Y37=0,"-",COUNTIFS('8. Folder'!B:B,CRUSCOTTO!U37,'8. Folder'!J:J,"Variante",'8. Folder'!M:M,"No")) -> - | U30: 4. Figurate SIP | V30: =SUM(W30:W33) -> 405 | W30: =IF(COUNTIF('8. Folder'!B:B,CRUSCOTTO!U30)=(CRUSCOTTO!X30+CRUSCOTTO!Y30),CRUSCOTTO!X30+CRUSCOTTO!Y30,"Errore") -> 13 | X30: =COUNTIFS('8. Folder'!B:B,CRUSCOTTO!U30,'8. Folder'!J:J,"-") -> 13 | Y30: =COUNTIFS('8. Folder'!B:B,CRUSCOTTO!U30,'8. Folder'!J:J,"Variante") -> 0 | Z30: =(W30-AA30)/W30 -> 0.84615385 | AA30: =IF(Y30=0,N23,N23+P23) -> 2 | AB30: =SUMIF('8. Folder'!B:B,CRUSCOTTO!U30,'8. Folder'!P:P) -> 430
B31: Usi Speciali | C31: 1. Parlamento | D31: =SUM(E31:E39) -> 660 | E31: =COUNTIF('12. Usi speciali'!B:B,C31) -> 14 | F31: =COUNTIFS('12. Usi speciali'!B:B,CRUSCOTTO!C31,'12. Usi speciali'!P:P,"Nuova")+COUNTIFS('12. Usi speciali'!B:B,CRUSCOTTO!C31,'12. Usi speciali'!P:P,"Usata")+COUNTIFS('12. Usi speciali'!B:B,CRUSCOTTO!C31,'12. Usi speciali'!P:P,"2a Scelta") -> 5 | G31: - | H31: =(F31)/E31 -> 0.35714286 | I31: =COUNTIFS('12. Usi speciali'!B:B,CRUSCOTTO!C31,'12. Usi speciali'!P:P,"Manca") -> 9 | J31: =SUMIF('12. Usi speciali'!B:B,CRUSCOTTO!C31,'12. Usi speciali'!S:S) -> 118 | M31: =SUM(M20:M30) -> 511 | N31: =SUM(N20:N30) -> 89 | O31: =SUM(O20:O30) -> 11 | P31: =SUM(P20:P30) -> 9 | U31: 5. Figurate Telecom lire | W31: =IF(COUNTIF('8. Folder'!B:B,CRUSCOTTO!U31)=(CRUSCOTTO!X31+CRUSCOTTO!Y31),CRUSCOTTO!X31+CRUSCOTTO!Y31,"Errore") -> 256 | X31: =COUNTIFS('8. Folder'!B:B,CRUSCOTTO!U31,'8. Folder'!J:J,"-") -> 242 | Y31: =COUNTIFS('8. Folder'!B:B,CRUSCOTTO!U31,'8. Folder'!J:J,"Variante") -> 14 | Z31: =(W31-AA31)/W31 -> 0.83984375 | AA31: =IF(Y31=0,N24,N24+P24) -> 41 | AB31: =SUMIF('8. Folder'!B:B,CRUSCOTTO!U31,'8. Folder'!P:P) -> 4509
C32: 2. Basi Nato | E32: =COUNTIF('12. Usi speciali'!B:B,C32) -> 6 | F32: =COUNTIFS('12. Usi speciali'!B:B,CRUSCOTTO!C32,'12. Usi speciali'!P:P,"Nuova")+COUNTIFS('12. Usi speciali'!B:B,CRUSCOTTO!C32,'12. Usi speciali'!P:P,"Usata")+COUNTIFS('12. Usi speciali'!B:B,CRUSCOTTO!C32,'12. Usi speciali'!P:P,"2a Scelta") -> 3 | G32: - | H32: =(F32)/E32 -> 0.5 | I32: =COUNTIFS('12. Usi speciali'!B:B,CRUSCOTTO!C32,'12. Usi speciali'!P:P,"Manca") -> 3 | J32: =SUMIF('12. Usi speciali'!B:B,CRUSCOTTO!C32,'12. Usi speciali'!S:S) -> 150 | U32: 6. Figurate Telecom euro | W32: =IF(COUNTIF('8. Folder'!B:B,CRUSCOTTO!U32)=(CRUSCOTTO!X32+CRUSCOTTO!Y32),CRUSCOTTO!X32+CRUSCOTTO!Y32,"Errore") -> 106 | X32: =COUNTIFS('8. Folder'!B:B,CRUSCOTTO!U32,'8. Folder'!J:J,"-") -> 101 | Y32: =COUNTIFS('8. Folder'!B:B,CRUSCOTTO!U32,'8. Folder'!J:J,"Variante") -> 5 | Z32: =(W32-AA32)/W32 -> 0.95283019 | AA32: =IF(Y32=0,N25,N25+P25) -> 5 | AB32: =SUMIF('8. Folder'!B:B,CRUSCOTTO!U32,'8. Folder'!P:P) -> 1655.5
C33: 3. Ospedali / Easytel | E33: =COUNTIF('12. Usi speciali'!B:B,C33) -> 33 | F33: =COUNTIFS('12. Usi speciali'!B:B,CRUSCOTTO!C33,'12. Usi speciali'!P:P,"Nuova")+COUNTIFS('12. Usi speciali'!B:B,CRUSCOTTO!C33,'12. Usi speciali'!P:P,"Usata")+COUNTIFS('12. Usi speciali'!B:B,CRUSCOTTO!C33,'12. Usi speciali'!P:P,"2a Scelta") -> 16 | G33: - | H33: =(F33)/E33 -> 0.48484848 | I33: =COUNTIFS('12. Usi speciali'!B:B,CRUSCOTTO!C33,'12. Usi speciali'!P:P,"Manca") -> 17 | J33: =SUMIF('12. Usi speciali'!B:B,CRUSCOTTO!C33,'12. Usi speciali'!S:S) -> 134 | U33: 7. Alto Adige | W33: =IF(COUNTIF('8. Folder'!B:B,CRUSCOTTO!U33)=(CRUSCOTTO!X33+CRUSCOTTO!Y33),CRUSCOTTO!X33+CRUSCOTTO!Y33,"Errore") -> 30 | X33: =COUNTIFS('8. Folder'!B:B,CRUSCOTTO!U33,'8. Folder'!J:J,"-") -> 30 | Y33: =COUNTIFS('8. Folder'!B:B,CRUSCOTTO!U33,'8. Folder'!J:J,"Variante") -> 0 | Z33: =(W33-AA33)/W33 -> 1 | AA33: =IF(Y33=0,N26,N26+P26) -> 0 | AB33: =SUMIF('8. Folder'!B:B,CRUSCOTTO!U33,'8. Folder'!P:P) -> 417
C34: 4. Carte di credito | E34: =COUNTIF('12. Usi speciali'!B:B,C34) -> 105 | F34: =COUNTIFS('12. Usi speciali'!B:B,CRUSCOTTO!C34,'12. Usi speciali'!P:P,"Nuova")+COUNTIFS('12. Usi speciali'!B:B,CRUSCOTTO!C34,'12. Usi speciali'!P:P,"Usata")+COUNTIFS('12. Usi speciali'!B:B,CRUSCOTTO!C34,'12. Usi speciali'!P:P,"2a Scelta") -> 22 | G34: - | H34: =(F34)/E34 -> 0.20952381 | I34: =COUNTIFS('12. Usi speciali'!B:B,CRUSCOTTO!C34,'12. Usi speciali'!P:P,"Manca") -> 83 | J34: =SUMIF('12. Usi speciali'!B:B,CRUSCOTTO!C34,'12. Usi speciali'!S:S) -> 440 | U34: 8. ADAC | V34: =SUM(W34:W36) -> 16 | W34: =IF(COUNTIF('8. Folder'!B:B,CRUSCOTTO!U34)=(CRUSCOTTO!X34+CRUSCOTTO!Y34),CRUSCOTTO!X34+CRUSCOTTO!Y34,"Errore") -> 3 | X34: =COUNTIFS('8. Folder'!B:B,CRUSCOTTO!U34,'8. Folder'!J:J,"-") -> 3 | Y34: =COUNTIFS('8. Folder'!B:B,CRUSCOTTO!U34,'8. Folder'!J:J,"Variante") -> 0 | Z34: =(W34-AA34)/W34 -> 1 | AA34: =IF(Y34=0,N27,N27+P27) -> 0 | AB34: =SUMIF('8. Folder'!B:B,CRUSCOTTO!U34,'8. Folder'!P:P) -> 75
C35: 5. Call-IT | E35: =COUNTIF('12. Usi speciali'!B:B,C35) -> 88 | F35: =COUNTIFS('12. Usi speciali'!B:B,CRUSCOTTO!C35,'12. Usi speciali'!P:P,"Nuova")+COUNTIFS('12. Usi speciali'!B:B,CRUSCOTTO!C35,'12. Usi speciali'!P:P,"Usata")+COUNTIFS('12. Usi speciali'!B:B,CRUSCOTTO!C35,'12. Usi speciali'!P:P,"2a Scelta") -> 5 | G35: - | H35: =(F35)/E35 -> 0.056818182 | I35: =COUNTIFS('12. Usi speciali'!B:B,CRUSCOTTO!C35,'12. Usi speciali'!P:P,"Manca") -> 83 | J35: =SUMIF('12. Usi speciali'!B:B,CRUSCOTTO!C35,'12. Usi speciali'!S:S) -> 71 | U35: 9. Chip | W35: =IF(COUNTIF('8. Folder'!B:B,CRUSCOTTO!U35)=(CRUSCOTTO!X35+CRUSCOTTO!Y35),CRUSCOTTO!X35+CRUSCOTTO!Y35,"Errore") -> 2 | X35: =COUNTIFS('8. Folder'!B:B,CRUSCOTTO!U35,'8. Folder'!J:J,"-") -> 2 | Y35: =COUNTIFS('8. Folder'!B:B,CRUSCOTTO!U35,'8. Folder'!J:J,"Variante") -> 0 | Z35: =(W35-AA35)/W35 -> 0.5 | AA35: =IF(Y35=0,N28,N28+P28) -> 1 | AB35: =SUMIF('8. Folder'!B:B,CRUSCOTTO!U35,'8. Folder'!P:P) -> 14
C36: 6. Sala Stampa | E36: =COUNTIF('12. Usi speciali'!B:B,C36) -> 175 | F36: =COUNTIFS('12. Usi speciali'!B:B,CRUSCOTTO!C36,'12. Usi speciali'!P:P,"Nuova")+COUNTIFS('12. Usi speciali'!B:B,CRUSCOTTO!C36,'12. Usi speciali'!P:P,"Usata")+COUNTIFS('12. Usi speciali'!B:B,CRUSCOTTO!C36,'12. Usi speciali'!P:P,"2a Scelta") -> 52 | G36: - | H36: =(F36)/E36 -> 0.29714286 | I36: =COUNTIFS('12. Usi speciali'!B:B,CRUSCOTTO!C36,'12. Usi speciali'!P:P,"Manca") -> 123 | J36: =SUMIF('12. Usi speciali'!B:B,CRUSCOTTO!C36,'12. Usi speciali'!S:S) -> 1418 | U36: 10. Generici | W36: =IF(COUNTIF('8. Folder'!B:B,CRUSCOTTO!U36)=(CRUSCOTTO!X36+CRUSCOTTO!Y36),CRUSCOTTO!X36+CRUSCOTTO!Y36,"Errore") -> 11 | X36: =COUNTIFS('8. Folder'!B:B,CRUSCOTTO!U36,'8. Folder'!J:J,"-") -> 11 | Y36: =COUNTIFS('8. Folder'!B:B,CRUSCOTTO!U36,'8. Folder'!J:J,"Variante") -> 0 | Z36: =(W36-AA36)/W36 -> 0.81818182 | AA36: =IF(Y36=0,N29,N29+P29) -> 2 | AB36: =SUMIF('8. Folder'!B:B,CRUSCOTTO!U36,'8. Folder'!P:P) -> 101
C37: 7. Mediaphone | E37: =COUNTIF('12. Usi speciali'!B:B,C37) -> 104 | F37: =COUNTIFS('12. Usi speciali'!B:B,CRUSCOTTO!C37,'12. Usi speciali'!P:P,"Nuova")+COUNTIFS('12. Usi speciali'!B:B,CRUSCOTTO!C37,'12. Usi speciali'!P:P,"Usata")+COUNTIFS('12. Usi speciali'!B:B,CRUSCOTTO!C37,'12. Usi speciali'!P:P,"2a Scelta") -> 74 | G37: - | H37: =(F37)/E37 -> 0.71153846 | I37: =COUNTIFS('12. Usi speciali'!B:B,CRUSCOTTO!C37,'12. Usi speciali'!P:P,"Manca") -> 30 | J37: =SUMIF('12. Usi speciali'!B:B,CRUSCOTTO!C37,'12. Usi speciali'!S:S) -> 2571 | U37: 11. Gadget e altro | V37: =W37 -> 54 | W37: =IF(COUNTIF('8. Folder'!B:B,CRUSCOTTO!U37)=(CRUSCOTTO!X37+CRUSCOTTO!Y37),CRUSCOTTO!X37+CRUSCOTTO!Y37,"Errore") -> 54 | X37: =COUNTIFS('8. Folder'!B:B,CRUSCOTTO!U37,'8. Folder'!J:J,"-") -> 54 | Y37: =COUNTIFS('8. Folder'!B:B,CRUSCOTTO!U37,'8. Folder'!J:J,"Variante") -> 0 | Z37: =(W37-AA37)/W37 -> 0.66666667 | AA37: =IF(Y37=0,N30,N30+P30) -> 18 | AB37: =SUMIF('8. Folder'!B:B,CRUSCOTTO!U37,'8. Folder'!P:P) -> 353.5
C38: 8. Prome | E38: =COUNTIF('12. Usi speciali'!B:B,C38) -> 69 | F38: =COUNTIFS('12. Usi speciali'!B:B,CRUSCOTTO!C38,'12. Usi speciali'!P:P,"Nuova")+COUNTIFS('12. Usi speciali'!B:B,CRUSCOTTO!C38,'12. Usi speciali'!P:P,"Usata")+COUNTIFS('12. Usi speciali'!B:B,CRUSCOTTO!C38,'12. Usi speciali'!P:P,"2a Scelta") -> 2 | G38: - | H38: =(F38)/E38 -> 0.028985507 | I38: =COUNTIFS('12. Usi speciali'!B:B,CRUSCOTTO!C38,'12. Usi speciali'!P:P,"Manca") -> 67 | J38: =SUMIF('12. Usi speciali'!B:B,CRUSCOTTO!C38,'12. Usi speciali'!S:S) -> 60 | W38: =SUM(W27:W37) -> 625 | X38: =SUM(X27:X37) -> 603 | Y38: =SUM(Y27:Y37) -> 22 | Z38: =(W38-AA38)/W38 -> 0.8432 | AA38: =N31+P31 -> 98 | AB38: =SUM(AB27:AB37) -> 9483
C39: 9. Giubileo e altri USP | E39: =COUNTIF('12. Usi speciali'!B:B,C39) -> 66 | F39: =COUNTIFS('12. Usi speciali'!B:B,CRUSCOTTO!C39,'12. Usi speciali'!P:P,"Nuova")+COUNTIFS('12. Usi speciali'!B:B,CRUSCOTTO!C39,'12. Usi speciali'!P:P,"Usata")+COUNTIFS('12. Usi speciali'!B:B,CRUSCOTTO!C39,'12. Usi speciali'!P:P,"2a Scelta") -> 7 | G39: - | H39: =(F39)/E39 -> 0.10606061 | I39: =COUNTIFS('12. Usi speciali'!B:B,CRUSCOTTO!C39,'12. Usi speciali'!P:P,"Manca") -> 59 | J39: =SUMIF('12. Usi speciali'!B:B,CRUSCOTTO!C39,'12. Usi speciali'!S:S) -> 144
E40: =SUM(E21:E39) -> 1444 | F40: =SUM(F21:F39) -> 428 | G40: =SUM(G21:G39) -> 0 | H40: =F40/E40 -> 0.29639889 | I40: =SUM(I21:I39) -> 1016 | J40: =SUM(J27:J39) -> 7265

Sheet 1. Precursorie
A1: Genere | B1: Sottogenere | C1: N.Golden | D1: N. C&C | E1: N. AG | F1: Taglio | G1: Scadenza | H1: Titolo | I1: Note | J1: Var | K1: Pr. | L1: Tiratura | M1: Val 2025 Nuova | N1: Val 2025 Usata | P1: Presente | Q1: Magnetizzazione | S1: Valore collezione
A2: 1. Precursorie | B2: 1. Sida | C2: P0 | D2: 1000 | E2: - | F2: - | G2: 1976 | H2: Sida 0 | I2: - | J2: - | K2: Pik | L2: - | M2: - | N2: P.A.R. | P2: Usata | Q2: Sì | S2: =IF(P2='Menu tendina'!A$5,0,IF(P2='Menu tendina'!A$4,'1. Precursorie'!N2/2,IF(P2='Menu tendina'!A$3,'1. Precursorie'!N2,IF(P2='Menu tendina'!A$2,'1. Precursorie'!M2,0)))) -> P.A.R.
A3: 1. Precursorie | B3: 1. Sida | C3: P1 | D3: 1001 | E3: P1 | F3: 2000 | G3: 1977 | H3: 1° Gruppo SIDA | I3: Bandella Circolare | J3: - | K3: Pik | L3: - | M3: 400 | N3: 300 | P3: Nuova | Q3: No | S3: =IF(P3='Menu tendina'!A$5,0,IF(P3='Menu tendina'!A$4,'1. Precursorie'!N3/2,IF(P3='Menu tendina'!A$3,'1. Precursorie'!N3,IF(P3='Menu tendina'!A$2,'1. Precursorie'!M3,0)))) -> 400
A4: 1. Precursorie | B4: 1. Sida | C4: P2 | D4: 1002 | E4: P2 | F4: 5000 | G4: 1977 | H4: 1° Gruppo SIDA | I4: Bandella Circolare | J4: - | K4: Pik | L4: - | M4: 500 | N4: 300 | P4: Manca | S4: =IF(P4='Menu tendina'!A$5,0,IF(P4='Menu tendina'!A$4,'1. Precursorie'!N4/2,IF(P4='Menu tendina'!A$3,'1. Precursorie'!N4,IF(P4='Menu tendina'!A$2,'1. Precursorie'!M4,0)))) -> 0
A5: 1. Precursorie | B5: 1. Sida | C5: P3 | D5: 1003 | E5: P3 | F5: 9000 | G5: 1977 | H5: 1° Gruppo SIDA | I5: Bandella Circolare | J5: - | K5: Pik | L5: - | M5: 400 | N5: 350 | P5: Manca | S5: =IF(P5='Menu tendina'!A$5,0,IF(P5='Menu tendina'!A$4,'1. Precursorie'!N5/2,IF(P5='Menu tendina'!A$3,'1. Precursorie'!N5,IF(P5='Menu tendina'!A$2,'1. Precursorie'!M5,0)))) -> 0
A6: 1. Precursorie | B6: 1. Sida | C6: P4 | D6: 1004 | E6: P4 | F6: 2000 | G6: 1978 | H6: 1° Gruppo SIDA | I6: Banella Sagomata | J6: - | K6: Pik | L6: 500 | M6: 380 | N6: 280 | P6: Nuova | Q6: Sì | S6: =IF(P6='Menu tendina'!A$5,0,IF(P6='Menu tendina'!A$4,'1. Precursorie'!N6/2,IF(P6='Menu tendina'!A$3,'1. Precursorie'!N6,IF(P6='Menu tendina'!A$2,'1. Precursorie'!M6,0)))) -> 380
A7: 1. Precursorie | B7: 1. Sida | C7: P5 | D7: - | E7: P5 | F7: 5000 | G7: 1978 | H7: 1° Gruppo SIDA | I7: (N.M.) Bandella Sagomata | J7: - | K7: Pik | L7: - | M7: P.A.R. | N7: P.A.R. | P7: Manca | Q7: n/a | S7: =IF(P7='Menu tendina'!A$5,0,IF(P7='Menu tendina'!A$4,'1. Precursorie'!N7/2,IF(P7='Menu tendina'!A$3,'1. Precursorie'!N7,IF(P7='Menu tendina'!A$2,'1. Precursorie'!M7,0)))) -> 0
A8: 1. Precursorie | B8: 1. Sida | C8: P6 | D8: 1005 | E8: P6 | F8: 9000 | G8: 1978 | H8: 1° Gruppo SIDA | I8: Bandella Sagomata | J8: - | K8: Pik | L8: 500 | M8: 450 | N8: 350 | P8: Nuova | Q8: No | S8: =IF(P8='Menu tendina'!A$5,0,IF(P8='Menu tendina'!A$4,'1. Precursorie'!N8/2,IF(P8='Menu tendina'!A$3,'1. Precursorie'!N8,IF(P8='Menu tendina'!A$2,'1. Precursorie'!M8,0)))) -> 450
A9: 1. Precursorie | B9: 1. Sida | C9: P7 | D9: 1006 | E9: P7 | F9: 2000 | G9: 28915 | H9: 1° Gruppo SIDA | I9: Bandella Sagomata | J9: - | K9: Pik | L9: 200 | M9: 250 | N9: 80 | P9: Nuova | S9: =IF(P9='Menu tendina'!A$5,0,IF(P9='Menu tendina'!A$4,'1. Precursorie'!N9/2,IF(P9='Menu tendina'!A$3,'1. Precursorie'!N9,IF(P9='Menu tendina'!A$2,'1. Precursorie'!M9,0)))) -> 250
A10: 1. Precursorie | B10: 1. Sida | C10: P7A | D10: 1006A | E10: P7A | F10: 2000 | G10: 28915 | H10: 1° Gruppo SIDA | I10: Bandella Diritta | J10: Variante | K10: Pik | L10: - | M10: 220 | N10: 130 | P10: Manca | S10: =IF(P10='Menu tendina'!A$5,0,IF(P10='Menu tendina'!A$4,'1. Precursorie'!N10/2,IF(P10='Menu tendina'!A$3,'1. Precursorie'!N10,IF(P10='Menu tendina'!A$2,'1. Precursorie'!M10,0)))) -> 0
A11: 1. Precursorie | B11: 1. Sida | C11: P7B | D11: 1006B | E11: P7B | F11: 2000 | G11: 28915 | H11: 1° Gruppo SIDA | I11: Badella Ridotta | J11: Variante | K11: Pik | L11: - | M11: 220 | N11: 130 | P11: Manca | S11: =IF(P11='Menu tendina'!A$5,0,IF(P11='Menu tendina'!A$4,'1. Precursorie'!N11/2,IF(P11='Menu tendina'!A$3,'1. Precursorie'!N11,IF(P11='Menu tendina'!A$2,'1. Precursorie'!M11,0)))) -> 0
A12: 1. Precursorie | B12: 1. Sida | C12: P8 | D12: 1007 | E12: P8 | F12: 5000 | G12: 28915 | H12: 1° Gruppo SIDA | I12: Bandella Sagomata | J12: - | K12: Pik | L12: 200 | M12: 250 | N12: 130 | P12: Usata | Q12: Sì | S12: =IF(P12='Menu tendina'!A$5,0,IF(P12='Menu tendina'!A$4,'1. Precursorie'!N12/2,IF(P12='Menu tendina'!A$3,'1. Precursorie'!N12,IF(P12='Menu tendina'!A$2,'1. Precursorie'!M12,0)))) -> 130
A13: 1. Precursorie | B13: 1. Sida | C13: P8A | D13: 1007A | E13: P8A | F13: 5000 | G13: 28915 | H13: 1° Gruppo SIDA | I13: Bandella Diritta | J13: Variante | K13: Pik | L13: - | M13: 220 | N13: 130 | P13: Manca | S13: =IF(P13='Menu tendina'!A$5,0,IF(P13='Menu tendina'!A$4,'1. Precursorie'!N13/2,IF(P13='Menu tendina'!A$3,'1. Precursorie'!N13,IF(P13='Menu tendina'!A$2,'1. Precursorie'!M13,0)))) -> 0
A14: 1. Precursorie | B14: 1. Sida | C14: P8B | D14: 1007B | E14: P8B | F14: 5000 | G14: 28915 | H14: 1° Gruppo SIDA | I14: Badella Ridotta | J14: Variante | K14: Pik | L14: - | M14: 220 | N14: 130 | P14: Nuova | Q14: Sì | S14: =IF(P14='Menu tendina'!A$5,0,IF(P14='Menu tendina'!A$4,'1. Precursorie'!N14/2,IF(P14='Menu tendina'!A$3,'1. Precursorie'!N14,IF(P14='Menu tendina'!A$2,'1. Precursorie'!M14,0)))) -> 220
A15: 1. Precursorie | B15: 1. Sida | C15: P9 | D15: 1008 | E15: P9 | F15: 9000 | G15: 28915 | H15: 1° Gruppo SIDA | I15: Bandella Sagomata | J15: - | K15: Pik | L15: 200 | M15: 80 | N15: 35 | P15: Nuova | Q15: Sì | S15: =IF(P15='Menu tendina'!A$5,0,IF(P15='Menu tendina'!A$4,'1. Precursorie'!N15/2,IF(P15='Menu tendina'!A$3,'1. Precursorie'!N15,IF(P15='Menu tendina'!A$2,'1. Precursorie'!M15,0)))) -> 80
A16: 1. Precursorie | B16: 1. Sida | C16: P9A | D16: 1008A | E16: P9A | F16: 9000 | G16: 28915 | H16: 1° Gruppo SIDA | I16: Bandella Diritta | J16: Variante | K16: Pik | L16: - | M16: 100 | N16: 55 | P16: Manca | S16: =IF(P16='Menu tendina'!A$5,0,IF(P16='Menu tendina'!A$4,'1. Precursorie'!N16/2,IF(P16='Menu tendina'!A$3,'1. Precursorie'!N16,IF(P16='Menu tendina'!A$2,'1. Precursorie'!M16,0)))) -> 0
A17: 1. Precursorie | B17: 1. Sida | C17: P9B | D17: 1008B | E17: P9B | F17: 9000 | G17: 28915 | H17: 1° Gruppo SIDA | I17: Badella Ridotta | J17: Variante | K17: Pik | L17: - | M17: 120 | N17: 55 | P17: Manca | S17: =IF(P17='Menu tendina'!A$5,0,IF(P17='Menu tendina'!A$4,'1. Precursorie'!N17/2,IF(P17='Menu tendina'!A$3,'1. Precursorie'!N17,IF(P17='Menu tendina'!A$2,'1. Precursorie'!M17,0)))) -> 0
A18: 1. Precursorie | B18: 1. Sida | C18: P10 | D18: 1009 | E18: P10 | F18: 2000 | G18: 29281 | H18: 1° Gruppo SIDA | I18: Bianca / Bandella Sagomata | J18: - | K18: Pik | L18: 200 | M18: 200 | N18: 120 | P18: Nuova | Q18: No | S18: =IF(P18='Menu tendina'!A$5,0,IF(P18='Menu tendina'!A$4,'1. Precursorie'!N18/2,IF(P18='Menu tendina'!A$3,'1. Precursorie'!N18,IF(P18='Menu tendina'!A$2,'1. Precursorie'!M18,0)))) -> 200
A19: 1. Precursorie | B19: 1. Sida | C19: P10A | D19: 1009A | E19: P10A | F19: 2000 | G19: 29281 | H19: 1° Gruppo SIDA | I19: Grigia / Bandella Sagomata | J19: Variante | K19: Pik | L19: 200 | M19: 250 | N19: 100 | P19: Manca | S19: =IF(P19='Menu tendina'!A$5,0,IF(P19='Menu tendina'!A$4,'1. Precursorie'!N19/2,IF(P19='Menu tendina'!A$3,'1. Precursorie'!N19,IF(P19='Menu tendina'!A$2,'1. Precursorie'!M19,0)))) -> 0
A20: 1. Precursorie | B20: 1. Sida | C20: P11 | D20: 1010 | E20: P11 | F20: 5000 | G20: 29281 | H20: 1° Gruppo SIDA | I20: Bianca / Bandella Sagomata | J20: - | K20: Pik | L20: 200 | M20: P.A.R. | N20: P.A.R. | P20: Manca | S20: =IF(P20='Menu tendina'!A$5,0,IF(P20='Menu tendina'!A$4,'1. Precursorie'!N20/2,IF(P20='Menu tendina'!A$3,'1. Precursorie'!N20,IF(P20='Menu tendina'!A$2,'1. Precursorie'!M20,0)))) -> 0
A21: 1. Precursorie | B21: 1. Sida | C21: P11A | D21: - | E21: - | F21: 5000 | G21: 29281 | H21: 1° Gruppo SIDA | I21: Grigia / Bandella Sagomata | J21: Variante | K21: Pik | L21: 200 | M21: P.A.R. | N21: P.A.R. | P21: Manca | S21: =IF(P21='Menu tendina'!A$5,0,IF(P21='Menu tendina'!A$4,'1. Precursorie'!N21/2,IF(P21='Menu tendina'!A$3,'1. Precursorie'!N21,IF(P21='Menu tendina'!A$2,'1. Precursorie'!M21,0)))) -> 0
A22: 1. Precursorie | B22: 1. Sida | C22: P12 | D22: 1010B | E22: P12 | F22: 9000 | G22: 29281 | H22: 1° Gruppo SIDA | I22: Bianca / Bandella Sagomata | J22: - | K22: Pik | L22: - | M22: P.A.R. | N22: P.A.R. | P22: Manca | S22: =IF(P22='Menu tendina'!A$5,0,IF(P22='Menu tendina'!A$4,'1. Precursorie'!N22/2,IF(P22='Menu tendina'!A$3,'1. Precursorie'!N22,IF(P22='Menu tendina'!A$2,'1. Precursorie'!M22,0)))) -> 0
A23: 1. Precursorie | B23: 1. Sida | C23: P13 | D23: 1011 | E23: P13 | F23: 2000 | G23: 29677 | H23: 1° Gruppo SIDA | I23: Bandella Sagomata | J23: - | K23: Pik | L23: 200 | M23: 20 | N23: 10 | P23: Nuova | Q23: No | S23: =IF(P23='Menu tendina'!A$5,0,IF(P23='Menu tendina'!A$4,'1. Precursorie'!N23/2,IF(P23='Menu tendina'!A$3,'1. Precursorie'!N23,IF(P23='Menu tendina'!A$2,'1. Precursorie'!M23,0)))) -> 20
A24: 1. Precursorie | B24: 1. Sida | C24: P13A | D24: 1011A | E24: P13A | F24: 2000 | G24: 29677 | H24: 1° Gruppo SIDA | I24: Bandella Diritta | J24: Variante | K24: Pik | L24: 200 | M24: 35 | N24: 15 | P24: Nuova | Q24: No | S24: =IF(P24='Menu tendina'!A$5,0,IF(P24='Menu tendina'!A$4,'1. Precursorie'!N24/2,IF(P24='Menu tendina'!A$3,'1. Precursorie'!N24,IF(P24='Menu tendina'!A$2,'1. Precursorie'!M24,0)))) -> 35
A25: 1. Precursorie | B25: 1. Sida | C25: P14 | D25: 1012 | E25: P14 | F25: 5000 | G25: 29677 | H25: 1° Gruppo SIDA | I25: Bandella Sagomata | J25: - | K25: Pik | L25: 200 | M25: 20 | N25: 10 | P25: Nuova | Q25: Sì | S25: =IF(P25='Menu tendina'!A$5,0,IF(P25='Menu tendina'!A$4,'1. Precursorie'!N25/2,IF(P25='Menu tendina'!A$3,'1. Precursorie'!N25,IF(P25='Menu tendina'!A$2,'1. Precursorie'!M25,0)))) -> 20
A26: 1. Precursorie | B26: 1. Sida | C26: P14A | D26: 1012A | E26: #N/A | F26: 5000 | G26: 29677 | H26: 1° Gruppo SIDA | I26: Bandella Diritta | J26: Variante | K26: Pik | L26: 200 | M26: 35 | N26: 15 | P26: Nuova | Q26: No | S26: =IF(P26='Menu tendina'!A$5,0,IF(P26='Menu tendina'!A$4,'1. Precursorie'!N26/2,IF(P26='Menu tendina'!A$3,'1. Precursorie'!N26,IF(P26='Menu tendina'!A$2,'1. Precursorie'!M26,0)))) -> 35
A27: 1. Precursorie | B27: 1. Sida | C27: P15 | D27: 1013 | E27: P15 | F27: 9000 | G27: 29677 | H27: 1° Gruppo SIDA | I27: Bandella Sagomata | J27: - | K27: Pik | L27: 200 | M27: 150 | N27: 25 | P27: Manca | S27: =IF(P27='Menu tendina'!A$5,0,IF(P27='Menu tendina'!A$4,'1. Precursorie'!N27/2,IF(P27='Menu tendina'!A$3,'1. Precursorie'!N27,IF(P27='Menu tendina'!A$2,'1. Precursorie'!M27,0)))) -> 0
